Workbook
Name S1Name: Inputs!$A$11
Name S1Alloc: Inputs!$C$11
Name S1Ret: Inputs!$D$11
Name S1Yld: Inputs!$E$11
Name S1Type: Inputs!$F$11
Name S1NR: Inputs!$G$11
Name S1TF: Inputs!$H$11
Name S1RR: Inputs!$I$11
Name S2Name: Inputs!$A$12
Name S2Alloc: Inputs!$C$12
Name S2Ret: Inputs!$D$12
Name S2Yld: Inputs!$E$12
Name S2Type: Inputs!$F$12
Name S2NR: Inputs!$G$12
Name S2TF: Inputs!$H$12
Name S2RR: Inputs!$I$12
Name S3Name: Inputs!$A$13
Name S3Alloc: Inputs!$C$13
Name S3Ret: Inputs!$D$13
Name S3Yld: Inputs!$E$13
Name S3Type: Inputs!$F$13
Name S3NR: Inputs!$G$13
Name S3TF: Inputs!$H$13
Name S3RR: Inputs!$I$13
Name S4Name: Inputs!$A$14
Name S4Alloc: Inputs!$C$14
Name S4Ret: Inputs!$D$14
Name S4Yld: Inputs!$E$14
Name S4Type: Inputs!$F$14
Name S4NR: Inputs!$G$14
Name S4TF: Inputs!$H$14
Name S4RR: Inputs!$I$14
Name S5Name: Inputs!$A$15
Name S5Alloc: Inputs!$C$15
Name S5Ret: Inputs!$D$15
Name S5Yld: Inputs!$E$15
Name S5Type: Inputs!$F$15
Name S5NR: Inputs!$G$15
Name S5TF: Inputs!$H$15
Name S5RR: Inputs!$I$15
Name S6Name: Inputs!$A$16
Name S6Alloc: Inputs!$C$16
Name S6Ret: Inputs!$D$16
Name S6Yld: Inputs!$E$16
Name S6Type: Inputs!$F$16
Name S6NR: Inputs!$G$16
Name S6TF: Inputs!$H$16
Name S6RR: Inputs!$I$16
Name HorizonM: Inputs!$B$45
Name HorizonY: Inputs!$B$46
Name ContribMonthly: Inputs!$B$47
Name CStartEff: Inputs!$B$48
Name CEndEff: Inputs!$B$49
Name WdMonthlyBase: Inputs!$B$50
Name WdStartEff: Inputs!$B$51
Name WdEndEff: Inputs!$B$52
Name RankNR: Inputs!$B$53
Name RankTF: Inputs!$B$54
Name RankRR: Inputs!$B$55
Name DS1: Inputs!$B$56

Sheet Dashboard
B1: Portfolio, Withdrawal & Tax Planner — Dashboard
B2: Canada (Ontario) · monthly engine · tax year 2026 rules. Edit the yellow cells on the Inputs tab; everything here updates automatically.
B4: Selected year | C4: 8 | D4: ="of "&HorizonY&" years" | F4: Key inputs (change on the Inputs tab): | M4: =MIN(MAX(1,N(SelYear)),HorizonY)
F5: ="Withdrawal: "&TEXT(N(WdAmt),"$#,##0")&" "&WdFreq&" from month "&WdStartEff
F6: ="Horizon: "&HorizonY&" yrs · Return override: "&TEXT(N(RetOverride),"+0.0%;-0.0%;0%")
B8: PORTFOLIO BALANCE | F8: TOTAL WITHDRAWN | J8: TOTAL TAX PAID (standalone)
B9: =INDEX('Projection'!$AA$4:$AA$53,SelYearEff) | F9: =INDEX('Projection'!$AB$4:$AB$53,SelYearEff) | J9: =SUMIFS('Tax Estimate'!$S$4:$S$53,'Tax Estimate'!$A$4:$A$53,"<="&SelYearEff)
B11: ="at end of year "&SelYearEff | F11: ="to date · "&TEXT(INDEX('Projection'!$Y$4:$Y$53,SelYearEff),"$#,##0")&" in year "&SelYearEff | J11: ="to date · stacked view adds "&TEXT(SUMIFS('Tax Estimate'!$AD$4:$AD$53,'Tax Estimate'!$A$4:$A$53,"<="&SelYearEff),"$#,##0")&" on top of other income"
B14: DIVIDENDS RECEIVED | F14: NET AFTER-TAX RETURN (annualized) | J14: PORTFOLIO LONGEVITY
B15: =SUMIFS('Projection'!$X$4:$X$53,'Projection'!$A$4:$A$53,"<="&SelYearEff) | F15: =IFERROR(POWER((INDEX('Projection'!$AA$4:$AA$53,SelYearEff)+INDEX('Projection'!$AB$4:$AB$53,SelYearEff)-SUMIFS('Tax Estimate'!$S$4:$S$53,'Tax Estimate'!$A$4:$A$53,"<="&SelYearEff))/(N(StartValue)+SUMIFS('Projection'!$V$4:$V$53,'Projection'!$A$4:$A$53,"<="&SelYearEff)),1/SelYearEff)-1,0) | J15: =IFERROR("Depletes in year "&(INT((MATCH(1,'Engine (Monthly)'!$DB$4:$DB$603,0)-1)/12)+1)&" ⚠","Lasts the full horizon ✅")
B17: ="all accounts, to end of year "&SelYearEff | F17: ="growth + dividends − tax, on money invested, to year "&SelYearEff | J17: ="the single most important wellbeing number"
B20: Sensitivity — expected return ±1%
C21: Return −1% | D21: Base plan | E21: Return +1%
B22: Ending balance | C22: =INDEX('Engine (-1%)'!$CX$3:$CX$603,HorizonM+1) | D22: =INDEX('Engine (Monthly)'!$CX$3:$CX$603,HorizonM+1) | E22: =INDEX('Engine (+1%)'!$CX$3:$CX$603,HorizonM+1)
B23: Depletes | C23: =IFERROR("Year "&(INT((MATCH(1,'Engine (-1%)'!$DB$4:$DB$603,0)-1)/12)+1)&" ⚠","Never (lasts)") | D23: =IFERROR("Year "&(INT((MATCH(1,'Engine (Monthly)'!$DB$4:$DB$603,0)-1)/12)+1)&" ⚠","Never (lasts)") | E23: =IFERROR("Year "&(INT((MATCH(1,'Engine (+1%)'!$DB$4:$DB$603,0)-1)/12)+1)&" ⚠","Never (lasts)")

Sheet Inputs
A1: Inputs — fill the yellow cells only
A2: Everything else in this workbook recalculates automatically. Grey cells are computed — do not edit.
A3: 1 · Portfolio setup
A4: Current total portfolio value (CAD) | B4: 500000 | D4: Market value of all accounts today.
A5: Projection horizon | B5: 20 | C5: Years | D5: Number + unit. Engine runs monthly (max 50 years).
A6: Annual inflation assumption | B6: 0.02 | D6: Used for withdrawal indexing and the real-dollar view.
A7: Expected-return override (± all sub-sections) | B7: 0 | D7: Adds to every sub-section's return. Leave 0% normally; scenario table uses ±1% around this.
A9: 2 · Sub-portfolio allocation (up to 6)
A10: Name | B10: Risk | C10: Alloc % | D10: Return %/yr (ex-div) | E10: Dividend yield %/yr | F10: Dividend type | G10: % Non-Reg | H10: % TFSA | I10: % RRSP/RRIF | J10: Row check
A11: Canadian Dividend Stocks | B11: Medium | C11: 0.3 | D11: 0.04 | E11: 0.04 | F11: Eligible | G11: 0.6 | H11: 0.2 | I11: 0.2 | J11: =IF(N($C11)=0,"",IF(ABS(N($G11)+N($H11)+N($I11)-1)<0.0001,"✓","⚠ accounts must total 100%"))
A12: US / Global Growth Equities | B12: High | C12: 0.3 | D12: 0.07 | E12: 0.012 | F12: Foreign / interest | G12: 0.4 | H12: 0.3 | I12: 0.3 | J12: =IF(N($C12)=0,"",IF(ABS(N($G12)+N($H12)+N($I12)-1)<0.0001,"✓","⚠ accounts must total 100%"))
A13: Bonds & GICs | B13: Low | C13: 0.25 | D13: 0.015 | E13: 0.035 | F13: Foreign / interest | G13: 0.2 | H13: 0.2 | I13: 0.6 | J13: =IF(N($C13)=0,"",IF(ABS(N($G13)+N($H13)+N($I13)-1)<0.0001,"✓","⚠ accounts must total 100%"))
A14: Canadian REITs | B14: Medium | C14: 0.15 | D14: 0.03 | E14: 0.045 | F14: Non-eligible | G14: 0.3 | H14: 0.4 | I14: 0.3 | J14: =IF(N($C14)=0,"",IF(ABS(N($G14)+N($H14)+N($I14)-1)<0.0001,"✓","⚠ accounts must total 100%"))
C15: 0 | D15: 0 | E15: 0 | F15: Eligible | G15: 0 | H15: 0 | I15: 0 | J15: =IF(N($C15)=0,"",IF(ABS(N($G15)+N($H15)+N($I15)-1)<0.0001,"✓","⚠ accounts must total 100%"))
C16: 0 | D16: 0 | E16: 0 | F16: Eligible | G16: 0 | H16: 0 | I16: 0 | J16: =IF(N($C16)=0,"",IF(ABS(N($G16)+N($H16)+N($I16)-1)<0.0001,"✓","⚠ accounts must total 100%"))
A17: Allocation check: | C17: =SUM(C11:C16) | E17: =IF(ABS(SUM($C$11:$C$16)-1)<0.0001,"✓ Allocations total 100%","⚠ Allocations must total 100% — currently "&TEXT(SUM($C$11:$C$16),"0.0%"))
A19: 3 · Contributions
A20: Contribution amount (CAD) | B20: 500 | D20: Per period (see frequency).
A21: Frequency | B21: Bi-weekly | D21: Weekly ×52/12, bi-weekly ×26/12 → monthly equivalent.
A22: Start month (1 = first month) | B22: 1
A23: End month (blank = end of horizon) | B23: 60 | D23: Many planners stop contributing when withdrawals start.
A24: Annual contribution escalation | B24: 0.03 | D24: Contribution grows this much every 12 months.
A25: Contribution destination | B25: Follow allocation % | D25: Or route 100% to one named sub-section.
A27: 4 · Withdrawals
A28: Withdrawal amount (CAD) | B28: 2000 | D28: Per period (see frequency).
A29: Frequency | B29: Monthly | D29: Bi-weekly ×26/12; Annual = withdrawn once every 12th month.
A30: Start month | B30: 61 | D30: e.g. 61 = start of year 6.
A31: End month (blank = end of horizon)
A32: Index withdrawals to inflation? | B32: Yes | D32: Steps up once per year by the inflation assumption.
A33: Funding order — 1st account drawn | B33: Non-Registered | D33: That month's dividends/cash in the account are used first,
A34: Funding order — 2nd account drawn | B34: TFSA | D34: then assets are sold pro-rata across its sub-sections.
A35: Funding order — 3rd account drawn | B35: RRSP/RRIF | D35: Each account must appear exactly once.
A36: Order check: | B36: =IF(AND(COUNTIF($B$33:$B$35,"Non-Registered")=1,COUNTIF($B$33:$B$35,"TFSA")=1,COUNTIF($B$33:$B$35,"RRSP/RRIF")=1),"✓ OK","⚠ each account exactly once")
A38: 5 · Tax settings
A39: Province | B39: Ontario | D39: Fixed for now; tax tables on the Assumptions tab are structured so other provinces can be added.
A40: Other annual taxable income (CAD) | B40: 60000 | D40: Used only for the "stacked" tax view.
A41: ACB today, as % of non-registered value | B41: 0.7 | D41: Adjusted cost base — gains are taxed on sale proceeds minus cost base.
A42: Reinvest dividends when not withdrawing? | B42: Yes | D42: If No, unused dividends accumulate as cash (0% return) in the account.
A44: Calculated values (do not edit) | L44: Destination options
A45: Horizon (months) | B45: =MIN(600,MAX(1,IF($C$5="Years",N($B$5)*12,N($B$5)))) | L45: Follow allocation %
...

Sheet Projection
A1: Projection — annual summary (all figures trace to the monthly Engine)
C2: Non-Registered | I2: TFSA | O2: RRSP/RRIF | U2: Total | AB2: Withdrawals Summary (cumulative)
A3: Year | B3: · | C3: Opening | D3: Contributions | E3: Growth | F3: Dividends | G3: Withdrawn | H3: Closing | I3: Opening | J3: Contributions | K3: Growth | L3: Dividends | M3: Withdrawn | N3: Closing | O3: Opening | P3: Contributions | Q3: Growth | R3: Dividends | S3: Withdrawn | T3: Closing | U3: Opening | V3: Contributions | W3: Growth | X3: Dividends | Y3: Withdrawn | Z3: Tax (standalone) | AA3: Closing | AB3: Total withdrawn | AC3: Funded by dividends/cash | AD3: Funded by asset sales | AE3: Realized gains | AF3: Status
A4: 1 | B4: =IF($A4<=HorizonY,1,0) | C4: =IF($B4=0,"",INDEX('Engine (Monthly)'!$AI$3:$AI$603,MIN(($A4-1)*12,HorizonM)+1)) | D4: =IF($B4=0,"",SUMIFS('Engine (Monthly)'!$X$4:$X$603,'Engine (Monthly)'!$C$4:$C$603,$A4)) | E4: =IF($B4=0,"",SUMIFS('Engine (Monthly)'!$AA$4:$AA$603,'Engine (Monthly)'!$C$4:$C$603,$A4)) | F4: =IF($B4=0,"",SUMIFS('Engine (Monthly)'!$Z$4:$Z$603,'Engine (Monthly)'!$C$4:$C$603,$A4)) | G4: =IF($B4=0,"",SUMIFS('Engine (Monthly)'!$AD$4:$AD$603,'Engine (Monthly)'!$C$4:$C$603,$A4)) | H4: =IF($B4=0,"",INDEX('Engine (Monthly)'!$AI$3:$AI$603,MIN($A4*12,HorizonM)+1)) | I4: =IF($B4=0,"",INDEX('Engine (Monthly)'!$BM$3:$BM$603,MIN(($A4-1)*12,HorizonM)+1)) | J4: =IF($B4=0,"",SUMIFS('Engine (Monthly)'!$BB$4:$BB$603,'Engine (Monthly)'!$C$4:$C$603,$A4)) | K4: =IF($B4=0,"",SUMIFS('Engine (Monthly)'!$BE$4:$BE$603,'Engine (Monthly)'!$C$4:$C$603,$A4)) | L4: =IF($B4=0,"",SUMIFS('Engine (Monthly)'!$BD$4:$BD$603,'Engine (Monthly)'!$C$4:$C$603,$A4)) | M4: =IF($B4=0,"",SUMIFS('Engine (Monthly)'!$BH$4:$BH$603,'Engine (Monthly)'!$C$4:$C$603,$A4)) | N4: =IF($B4=0,"",INDEX('Engine (Monthly)'!$BM$3:$BM$603,MIN($A4*12,HorizonM)+1)) | O4: =IF($B4=0,"",INDEX('Engine (Monthly)'!$CQ$3:$CQ$603,MIN(($A4-1)*12,HorizonM)+1)) | P4: =IF($B4=0,"",SUMIFS('Engine (Monthly)'!$CF$4:$CF$603,'Engine (Monthly)'!$C$4:$C$603,$A4)) | Q4: =IF($B4=0,"",SUMIFS('Engine (Monthly)'!$CI$4:$CI$603,'Engine (Monthly)'!$C$4:$C$603,$A4)) | R4: =IF($B4=0,"",SUMIFS('Engine (Monthly)'!$CH$4:$CH$603,'Engine (Monthly)'!$C$4:$C$603,$A4)) | S4: =IF($B4=0,"",SUMIFS('Engine (Monthly)'!$CL$4:$CL$603,'Engine (Monthly)'!$C$4:$C$603,$A4)) | T4: =IF($B4=0,"",INDEX('Engine (Monthly)'!$CQ$3:$CQ$603,MIN($A4*12,HorizonM)+1)) | U4: =IF($B4=0,"",$C4+$I4+$O4) | V4: =IF($B4=0,"",$D4+$J4+$P4) | W4: =IF($B4=0,"",$E4+$K4+$Q4) | X4: =IF($B4=0,"",$F4+$L4+$R4) | Y4: =IF($B4=0,"",$G4+$M4+$S4) | Z4: =IF($B4=0,"",'Tax Estimate'!$S4) | AA4: =IF($B4=0,"",$H4+$N4+$T4) | AB4: =IF($B4=0,"",SUMIFS('Engine (Monthly)'!$CY$4:$CY$603,'Engine (Monthly)'!$C$4:$C$603,"<="&$A4)) | AC4: =IF($B4=0,"",SUMIFS('Engine (Monthly)'!$CZ$4:$CZ$603,'Engine (Monthly)'!$C$4:$C$603,"<="&$A4)) | AD4: =IF($B4=0,"",SUMIFS('Engine (Monthly)'!$DA$4:$DA$603,'Engine (Monthly)'!$C$4:$C$603,"<="&$A4)) | AE4: =IF($B4=0,"",SUMIFS('Engine (Monthly)'!$CV$4:$CV$603,'Engine (Monthly)'!$C$4:$C$603,"<="&$A4)) | AF4: =IF($B4=0,"",IF(COUNTIFS('Engine (Monthly)'!$C$4:$C$603,$A4,'Engine (Monthly)'!$DB$4:$DB$603,1)>0,"⚠ shortfall","OK"))
A5: 2 | B5: =IF($A5<=HorizonY,1,0) | C5: =IF($B5=0,"",INDEX('Engine (Monthly)'!$AI$3:$AI$603,MIN(($A5-1)*12,HorizonM)+1)) | D5: =IF($B5=0,"",SUMIFS('Engine (Monthly)'!$X$4:$X$603,'Engine (Monthly)'!$C$4:$C$603,$A5)) | E5: =IF($B5=0,"",SUMIFS('Engine (Monthly)'!$AA$4:$AA$603,'Engine (Monthly)'!$C$4:$C$603,$A5)) | F5: =IF($B5=0,"",SUMIFS('Engine (Monthly)'!$Z$4:$Z$603,'Engine (Monthly)'!$C$4:$C$603,$A5)) | G5: =IF($B5=0,"",SUMIFS('Engine (Monthly)'!$AD$4:$AD$603,'Engine (Monthly)'!$C$4:$C$603,$A5)) | H5: =IF($B5=0,"",INDEX('Engine (Monthly)'!$AI$3:$AI$603,MIN($A5*12,HorizonM)+1)) | I5: =IF($B5=0,"",INDEX('Engine (Monthly)'!$BM$3:$BM$603,MIN(($A5-1)*12,HorizonM)+1)) | J5: =IF($B5=0,"",SUMIFS('Engine (Monthly)'!$BB$4:$BB$603,'Engine (Monthly)'!$C$4:$C$603,$A5)) | K5: =IF($B5=0,"",SUMIFS('Engine (Monthly)'!$BE$4:$BE$603,'Engine (Monthly)'!$C$4:$C$603,$A5)) | L5: =IF($B5=0,"",SUMIFS('Engine (Monthly)'!$BD$4:$BD$603,'Engine (Monthly)'!$C$4:$C$603,$A5)) | M5: =IF($B5=0,"",SUMIFS('Engine (Monthly)'!$BH$4:$BH$603,'Engine (Monthly)'!$C$4:$C$603,$A5)) | N5: =IF($B5=0,"",INDEX('Engine (Monthly)'!$BM$3:$BM$603,MIN($A5*12,HorizonM)+1)) | O5: =IF($B5=0,"",INDEX('Engine (Monthly)'!$CQ$3:$CQ$603,MIN(($A5-1)*12,HorizonM)+1)) | P5: =IF($B5=0,"",SUMIFS('Engine (Monthly)'!$CF$4:$CF$603,'Engine (Monthly)'!$C$4:$C$603,$A5)) | Q5: =IF($B5=0,"",SUMIFS('Engine (Monthly)'!$CI$4:$CI$603,'Engine (Monthly)'!$C$4:$C$603,$A5)) | R5: =IF($B5=0,"",SUMIFS('Engine (Monthly)'!$CH$4:$CH$603,'Engine (Monthly)'!$C$4:$C$603,$A5)) | S5: =IF($B5=0,"",SUMIFS('Engine (Monthly)'!$CL$4:$CL$603,'Engine (Monthly)'!$C$4:$C$603,$A5)) | T5: =IF($B5=0,"",INDEX('Engine (Monthly)'!$CQ$3:$CQ$603,MIN($A5*12,HorizonM)+1)) | U5: =IF($B5=0,"",$C5+$I5+$O5) | V5: =IF($B5=0,"",$D5+$J5+$P5) | W5: =IF($B5=0,"",$E5+$K5+$Q5) | X5: =IF($B5=0,"",$F5+$L5+$R5) | Y5: =IF($B5=0,"",$G5+$M5+$S5) | Z5: =IF($B5=0,"",'Tax Estimate'!$S5) | AA5: =IF($B5=0,"",$H5+$N5+$T5) | AB5: =IF($B5=0,"",SUMIFS('Engine (Monthly)'!$CY$4:$CY$603,'Engine (Monthly)'!$C$4:$C$603,"<="&$A5)) | AC5: =IF($B5=0,"",SUMIFS('Engine (Monthly)'!$CZ$4:$CZ$603,'Engine (Monthly)'!$C$4:$C$603,"<="&$A5)) | AD5: =IF($B5=0,"",SUMIFS('Engine (Monthly)'!$DA$4:$DA$603,'Engine (Monthly)'!$C$4:$C$603,"<="&$A5)) | AE5: =IF($B5=0,"",SUMIFS('Engine (Monthly)'!$CV$4:$CV$603,'Engine (Monthly)'!$C$4:$C$603,"<="&$A5)) | AF5: =IF($B5=0,"",IF(COUNTIFS('Engine (Monthly)'!$C$4:$C$603,$A5,'Engine (Monthly)'!$DB$4:$DB$603,1)>0,"⚠ shortfall","OK"))
A6: 3 | B6: =IF($A6<=HorizonY,1,0) | C6: =IF($B6=0,"",INDEX('Engine (Monthly)'!$AI$3:$AI$603,MIN(($A6-1)*12,HorizonM)+1)) | D6: =IF($B6=0,"",SUMIFS('Engine (Monthly)'!$X$4:$X$603,'Engine (Monthly)'!$C$4:$C$603,$A6)) | E6: =IF($B6=0,"",SUMIFS('Engine (Monthly)'!$AA$4:$AA$603,'Engine (Monthly)'!$C$4:$C$603,$A6)) | F6: =IF($B6=0,"",SUMIFS('Engine (Monthly)'!$Z$4:$Z$603,'Engine (Monthly)'!$C$4:$C$603,$A6)) | G6: =IF($B6=0,"",SUMIFS('Engine (Monthly)'!$AD$4:$AD$603,'Engine (Monthly)'!$C$4:$C$603,$A6)) | H6: =IF($B6=0,"",INDEX('Engine (Monthly)'!$AI$3:$AI$603,MIN($A6*12,HorizonM)+1)) | I6: =IF($B6=0,"",INDEX('Engine (Monthly)'!$BM$3:$BM$603,MIN(($A6-1)*12,HorizonM)+1)) | J6: =IF($B6=0,"",SUMIFS('Engine (Monthly)'!$BB$4:$BB$603,'Engine (Monthly)'!$C$4:$C$603,$A6)) | K6: =IF($B6=0,"",SUMIFS('Engine (Monthly)'!$BE$4:$BE$603,'Engine (Monthly)'!$C$4:$C$603,$A6)) | L6: =IF($B6=0,"",SUMIFS('Engine (Monthly)'!$BD$4:$BD$603,'Engine (Monthly)'!$C$4:$C$603,$A6)) | M6: =IF($B6=0,"",SUMIFS('Engine (Monthly)'!$BH$4:$BH$603,'Engine (Monthly)'!$C$4:$C$603,$A6)) | N6: =IF($B6=0,"",INDEX('Engine (Monthly)'!$BM$3:$BM$603,MIN($A6*12,HorizonM)+1)) | O6: =IF($B6=0,"",INDEX('Engine (Monthly)'!$CQ$3:$CQ$603,MIN(($A6-1)*12,HorizonM)+1)) | P6: =IF($B6=0,"",SUMIFS('Engine (Monthly)'!$CF$4:$CF$603,'Engine (Monthly)'!$C$4:$C$603,$A6)) | Q6: =IF($B6=0,"",SUMIFS('Engine (Monthly)'!$CI$4:$CI$603,'Engine (Monthly)'!$C$4:$C$603,$A6)) | R6: =IF($B6=0,"",SUMIFS('Engine (Monthly)'!$CH$4:$CH$603,'Engine (Monthly)'!$C$4:$C$603,$A6)) | S6: =IF($B6=0,"",SUMIFS('Engine (Monthly)'!$CL$4:$CL$603,'Engine (Monthly)'!$C$4:$C$603,$A6)) | T6: =IF($B6=0,"",INDEX('Engine (Monthly)'!$CQ$3:$CQ$603,MIN($A6*12,HorizonM)+1)) | U6: =IF($B6=0,"",$C6+$I6+$O6) | V6: =IF($B6=0,"",$D6+$J6+$P6) | W6: =IF($B6=0,"",$E6+$K6+$Q6) | X6: =IF($B6=0,"",$F6+$L6+$R6) | Y6: =IF($B6=0,"",$G6+$M6+$S6) | Z6: =IF($B6=0,"",'Tax Estimate'!$S6) | AA6: =IF($B6=0,"",$H6+$N6+$T6) | AB6: =IF($B6=0,"",SUMIFS('Engine (Monthly)'!$CY$4:$CY$603,'Engine (Monthly)'!$C$4:$C$603,"<="&$A6)) | AC6: =IF($B6=0,"",SUMIFS('Engine (Monthly)'!$CZ$4:$CZ$603,'Engine (Monthly)'!$C$4:$C$603,"<="&$A6)) | AD6: =IF($B6=0,"",SUMIFS('Engine (Monthly)'!$DA$4:$DA$603,'Engine (Monthly)'!$C$4:$C$603,"<="&$A6)) | AE6: =IF($B6=0,"",SUMIFS('Engine (Monthly)'!$CV$4:$CV$603,'Engine (Monthly)'!$C$4:$C$603,"<="&$A6)) | AF6: =IF($B6=0,"",IF(COUNTIFS('Engine (Monthly)'!$C$4:$C$603,$A6,'Engine (Monthly)'!$DB$4:$DB$603,1)>0,"⚠ shortfall","OK"))
A7: 4 | B7: =IF($A7<=HorizonY,1,0) | C7: =IF($B7=0,"",INDEX('Engine (Monthly)'!$AI$3:$AI$603,MIN(($A7-1)*12,HorizonM)+1)) | D7: =IF($B7=0,"",SUMIFS('Engine (Monthly)'!$X$4:$X$603,'Engine (Monthly)'!$C$4:$C$603,$A7)) | E7: =IF($B7=0,"",SUMIFS('Engine (Monthly)'!$AA$4:$AA$603,'Engine (Monthly)'!$C$4:$C$603,$A7)) | F7: =IF($B7=0,"",SUMIFS('Engine (Monthly)'!$Z$4:$Z$603,'Engine (Monthly)'!$C$4:$C$603,$A7)) | G7: =IF($B7=0,"",SUMIFS('Engine (Monthly)'!$AD$4:$AD$603,'Engine (Monthly)'!$C$4:$C$603,$A7)) | H7: =IF($B7=0,"",INDEX('Engine (Monthly)'!$AI$3:$AI$603,MIN($A7*12,HorizonM)+1)) | I7: =IF($B7=0,"",INDEX('Engine (Monthly)'!$BM$3:$BM$603,MIN(($A7-1)*12,HorizonM)+1)) | J7: =IF($B7=0,"",SUMIFS('Engine (Monthly)'!$BB$4:$BB$603,'Engine (Monthly)'!$C$4:$C$603,$A7)) | K7: =IF($B7=0,"",SUMIFS('Engine (Monthly)'!$BE$4:$BE$603,'Engine (Monthly)'!$C$4:$C$603,$A7)) | L7: =IF($B7=0,"",SUMIFS('Engine (Monthly)'!$BD$4:$BD$603,'Engine (Monthly)'!$C$4:$C$603,$A7)) | M7: =IF($B7=0,"",SUMIFS('Engine (Monthly)'!$BH$4:$BH$603,'Engine (Monthly)'!$C$4:$C$603,$A7)) | N7: =IF($B7=0,"",INDEX('Engine (Monthly)'!$BM$3:$BM$603,MIN($A7*12,HorizonM)+1)) | O7: =IF($B7=0,"",INDEX('Engine (Monthly)'!$CQ$3:$CQ$603,MIN(($A7-1)*12,HorizonM)+1)) | P7: =IF($B7=0,"",SUMIFS('Engine (Monthly)'!$CF$4:$CF$603,'Engine (Monthly)'!$C$4:$C$603,$A7)) | Q7: =IF($B7=0,"",SUMIFS('Engine (Monthly)'!$CI$4:$CI$603,'Engine (Monthly)'!$C$4:$C$603,$A7)) | R7: =IF($B7=0,"",SUMIFS('Engine (Monthly)'!$CH$4:$CH$603,'Engine (Monthly)'!$C$4:$C$603,$A7)) | S7: =IF($B7=0,"",SUMIFS('Engine (Monthly)'!$CL$4:$CL$603,'Engine (Monthly)'!$C$4:$C$603,$A7)) | T7: =IF($B7=0,"",INDEX('Engine (Monthly)'!$CQ$3:$CQ$603,MIN($A7*12,HorizonM)+1)) | U7: =IF($B7=0,"",$C7+$I7+$O7) | V7: =IF($B7=0,"",$D7+$J7+$P7) | W7: =IF($B7=0,"",$E7+$K7+$Q7) | X7: =IF($B7=0,"",$F7+$L7+$R7) | Y7: =IF($B7=0,"",$G7+$M7+$S7) | Z7: =IF($B7=0,"",'Tax Estimate'!$S7) | AA7: =IF($B7=0,"",$H7+$N7+$T7) | AB7: =IF($B7=0,"",SUMIFS('Engine (Monthly)'!$CY$4:$CY$603,'Engine (Monthly)'!$C$4:$C$603,"<="&$A7)) | AC7: =IF($B7=0,"",SUMIFS('Engine (Monthly)'!$CZ$4:$CZ$603,'Engine (Monthly)'!$C$4:$C$603,"<="&$A7)) | AD7: =IF($B7=0,"",SUMIFS('Engine (Monthly)'!$DA$4:$DA$603,'Engine (Monthly)'!$C$4:$C$603,"<="&$A7)) | AE7: =IF($B7=0,"",SUMIFS('Engine (Monthly)'!$CV$4:$CV$603,'Engine (Monthly)'!$C$4:$C$603,"<="&$A7)) | AF7: =IF($B7=0,"",IF(COUNTIFS('Engine (Monthly)'!$C$4:$C$603,$A7,'Engine (Monthly)'!$DB$4:$DB$603,1)>0,"⚠ shortfall","OK"))
A8: 5 | B8: =IF($A8<=HorizonY,1,0) | C8: =IF($B8=0,"",INDEX('Engine (Monthly)'!$AI$3:$AI$603,MIN(($A8-1)*12,HorizonM)+1)) | D8: =IF($B8=0,"",SUMIFS('Engine (Monthly)'!$X$4:$X$603,'Engine (Monthly)'!$C$4:$C$603,$A8)) | E8: =IF($B8=0,"",SUMIFS('Engine (Monthly)'!$AA$4:$AA$603,'Engine (Monthly)'!$C$4:$C$603,$A8)) | F8: =IF($B8=0,"",SUMIFS('Engine (Monthly)'!$Z$4:$Z$603,'Engine (Monthly)'!$C$4:$C$603,$A8)) | G8: =IF($B8=0,"",SUMIFS('Engine (Monthly)'!$AD$4:$AD$603,'Engine (Monthly)'!$C$4:$C$603,$A8)) | H8: =IF($B8=0,"",INDEX('Engine (Monthly)'!$AI$3:$AI$603,MIN($A8*12,HorizonM)+1)) | I8: =IF($B8=0,"",INDEX('Engine (Monthly)'!$BM$3:$BM$603,MIN(($A8-1)*12,HorizonM)+1)) | J8: =IF($B8=0,"",SUMIFS('Engine (Monthly)'!$BB$4:$BB$603,'Engine (Monthly)'!$C$4:$C$603,$A8)) | K8: =IF($B8=0,"",SUMIFS('Engine (Monthly)'!$BE$4:$BE$603,'Engine (Monthly)'!$C$4:$C$603,$A8)) | L8: =IF($B8=0,"",SUMIFS('Engine (Monthly)'!$BD$4:$BD$603,'Engine (Monthly)'!$C$4:$C$603,$A8)) | M8: =IF($B8=0,"",SUMIFS('Engine (Monthly)'!$BH$4:$BH$603,'Engine (Monthly)'!$C$4:$C$603,$A8)) | N8: =IF($B8=0,"",INDEX('Engine (Monthly)'!$BM$3:$BM$603,MIN($A8*12,HorizonM)+1)) | O8: =IF($B8=0,"",INDEX('Engine (Monthly)'!$CQ$3:$CQ$603,MIN(($A8-1)*12,HorizonM)+1)) | P8: =IF($B8=0,"",SUMIFS('Engine (Monthly)'!$CF$4:$CF$603,'Engine (Monthly)'!$C$4:$C$603,$A8)) | Q8: =IF($B8=0,"",SUMIFS('Engine (Monthly)'!$CI$4:$CI$603,'Engine (Monthly)'!$C$4:$C$603,$A8)) | R8: =IF($B8=0,"",SUMIFS('Engine (Monthly)'!$CH$4:$CH$603,'Engine (Monthly)'!$C$4:$C$603,$A8)) | S8: =IF($B8=0,"",SUMIFS('Engine (Monthly)'!$CL$4:$CL$603,'Engine (Monthly)'!$C$4:$C$603,$A8)) | T8: =IF($B8=0,"",INDEX('Engine (Monthly)'!$CQ$3:$CQ$603,MIN($A8*12,HorizonM)+1)) | U8: =IF($B8=0,"",$C8+$I8+$O8) | V8: =IF($B8=0,"",$D8+$J8+$P8) | W8: =IF($B8=0,"",$E8+$K8+$Q8) | X8: =IF($B8=0,"",$F8+$L8+$R8) | Y8: =IF($B8=0,"",$G8+$M8+$S8) | Z8: =IF($B8=0,"",'Tax Estimate'!$S8) | AA8: =IF($B8=0,"",$H8+$N8+$T8) | AB8: =IF($B8=0,"",SUMIFS('Engine (Monthly)'!$CY$4:$CY$603,'Engine (Monthly)'!$C$4:$C$603,"<="&$A8)) | AC8: =IF($B8=0,"",SUMIFS('Engine (Monthly)'!$CZ$4:$CZ$603,'Engine (Monthly)'!$C$4:$C$603,"<="&$A8)) | AD8: =IF($B8=0,"",SUMIFS('Engine (Monthly)'!$DA$4:$DA$603,'Engine (Monthly)'!$C$4:$C$603,"<="&$A8)) | AE8: =IF($B8=0,"",SUMIFS('Engine (Monthly)'!$CV$4:$CV$603,'Engine (Monthly)'!$C$4:$C$603,"<="&$A8)) | AF8: =IF($B8=0,"",IF(COUNTIFS('Engine (Monthly)'!$C$4:$C$603,$A8,'Engine (Monthly)'!$DB$4:$DB$603,1)>0,"⚠ shortfall","OK"))
A9: 6 | B9: =IF($A9<=HorizonY,1,0) | C9: =IF($B9=0,"",INDEX('Engine (Monthly)'!$AI$3:$AI$603,MIN(($A9-1)*12,HorizonM)+1)) | D9: =IF($B9=0,"",SUMIFS('Engine (Monthly)'!$X$4:$X$603,'Engine (Monthly)'!$C$4:$C$603,$A9)) | E9: =IF($B9=0,"",SUMIFS('Engine (Monthly)'!$AA$4:$AA$603,'Engine (Monthly)'!$C$4:$C$603,$A9)) | F9: =IF($B9=0,"",SUMIFS('Engine (Monthly)'!$Z$4:$Z$603,'Engine (Monthly)'!$C$4:$C$603,$A9)) | G9: =IF($B9=0,"",SUMIFS('Engine (Monthly)'!$AD$4:$AD$603,'Engine (Monthly)'!$C$4:$C$603,$A9)) | H9: =IF($B9=0,"",INDEX('Engine (Monthly)'!$AI$3:$AI$603,MIN($A9*12,HorizonM)+1)) | I9: =IF($B9=0,"",INDEX('Engine (Monthly)'!$BM$3:$BM$603,MIN(($A9-1)*12,HorizonM)+1)) | J9: =IF($B9=0,"",SUMIFS('Engine (Monthly)'!$BB$4:$BB$603,'Engine (Monthly)'!$C$4:$C$603,$A9)) | K9: =IF($B9=0,"",SUMIFS('Engine (Monthly)'!$BE$4:$BE$603,'Engine (Monthly)'!$C$4:$C$603,$A9)) | L9: =IF($B9=0,"",SUMIFS('Engine (Monthly)'!$BD$4:$BD$603,'Engine (Monthly)'!$C$4:$C$603,$A9)) | M9: =IF($B9=0,"",SUMIFS('Engine (Monthly)'!$BH$4:$BH$603,'Engine (Monthly)'!$C$4:$C$603,$A9)) | N9: =IF($B9=0,"",INDEX('Engine (Monthly)'!$BM$3:$BM$603,MIN($A9*12,HorizonM)+1)) | O9: =IF($B9=0,"",INDEX('Engine (Monthly)'!$CQ$3:$CQ$603,MIN(($A9-1)*12,HorizonM)+1)) | P9: =IF($B9=0,"",SUMIFS('Engine (Monthly)'!$CF$4:$CF$603,'Engine (Monthly)'!$C$4:$C$603,$A9)) | Q9: =IF($B9=0,"",SUMIFS('Engine (Monthly)'!$CI$4:$CI$603,'Engine (Monthly)'!$C$4:$C$603,$A9)) | R9: =IF($B9=0,"",SUMIFS('Engine (Monthly)'!$CH$4:$CH$603,'Engine (Monthly)'!$C$4:$C$603,$A9)) | S9: =IF($B9=0,"",SUMIFS('Engine (Monthly)'!$CL$4:$CL$603,'Engine (Monthly)'!$C$4:$C$603,$A9)) | T9: =IF($B9=0,"",INDEX('Engine (Monthly)'!$CQ$3:$CQ$603,MIN($A9*12,HorizonM)+1)) | U9: =IF($B9=0,"",$C9+$I9+$O9) | V9: =IF($B9=0,"",$D9+$J9+$P9) | W9: =IF($B9=0,"",$E9+$K9+$Q9) | X9: =IF($B9=0,"",$F9+$L9+$R9) | Y9: =IF($B9=0,"",$G9+$M9+$S9) | Z9: =IF($B9=0,"",'Tax Estimate'!$S9) | AA9: =IF($B9=0,"",$H9+$N9+$T9) | AB9: =IF($B9=0,"",SUMIFS('Engine (Monthly)'!$CY$4:$CY$603,'Engine (Monthly)'!$C$4:$C$603,"<="&$A9)) | AC9: =IF($B9=0,"",SUMIFS('Engine (Monthly)'!$CZ$4:$CZ$603,'Engine (Monthly)'!$C$4:$C$603,"<="&$A9)) | AD9: =IF($B9=0,"",SUMIFS('Engine (Monthly)'!$DA$4:$DA$603,'Engine (Monthly)'!$C$4:$C$603,"<="&$A9)) | AE9: =IF($B9=0,"",SUMIFS('Engine (Monthly)'!$CV$4:$CV$603,'Engine (Monthly)'!$C$4:$C$603,"<="&$A9)) | AF9: =IF($B9=0,"",IF(COUNTIFS('Engine (Monthly)'!$C$4:$C$603,$A9,'Engine (Monthly)'!$DB$4:$DB$603,1)>0,"⚠ shortfall","OK"))
A10: 7 | B10: =IF($A10<=HorizonY,1,0) | C10: =IF($B10=0,"",INDEX('Engine (Monthly)'!$AI$3:$AI$603,MIN(($A10-1)*12,HorizonM)+1)) | D10: =IF($B10=0,"",SUMIFS('Engine (Monthly)'!$X$4:$X$603,'Engine (Monthly)'!$C$4:$C$603,$A10)) | E10: =IF($B10=0,"",SUMIFS('Engine (Monthly)'!$AA$4:$AA$603,'Engine (Monthly)'!$C$4:$C$603,$A10)) | F10: =IF($B10=0,"",SUMIFS('Engine (Monthly)'!$Z$4:$Z$603,'Engine (Monthly)'!$C$4:$C$603,$A10)) | G10: =IF($B10=0,"",SUMIFS('Engine (Monthly)'!$AD$4:$AD$603,'Engine (Monthly)'!$C$4:$C$603,$A10)) | H10: =IF($B10=0,"",INDEX('Engine (Monthly)'!$AI$3:$AI$603,MIN($A10*12,HorizonM)+1)) | I10: =IF($B10=0,"",INDEX('Engine (Monthly)'!$BM$3:$BM$603,MIN(($A10-1)*12,HorizonM)+1)) | J10: =IF($B10=0,"",SUMIFS('Engine (Monthly)'!$BB$4:$BB$603,'Engine (Monthly)'!$C$4:$C$603,$A10)) | K10: =IF($B10=0,"",SUMIFS('Engine (Monthly)'!$BE$4:$BE$603,'Engine (Monthly)'!$C$4:$C$603,$A10)) | L10: =IF($B10=0,"",SUMIFS('Engine (Monthly)'!$BD$4:$BD$603,'Engine (Monthly)'!$C$4:$C$603,$A10)) | M10: =IF($B10=0,"",SUMIFS('Engine (Monthly)'!$BH$4:$BH$603,'Engine (Monthly)'!$C$4:$C$603,$A10)) | N10: =IF($B10=0,"",INDEX('Engine (Monthly)'!$BM$3:$BM$603,MIN($A10*12,HorizonM)+1)) | O10: =IF($B10=0,"",INDEX('Engine (Monthly)'!$CQ$3:$CQ$603,MIN(($A10-1)*12,HorizonM)+1)) | P10: =IF($B10=0,"",SUMIFS('Engine (Monthly)'!$CF$4:$CF$603,'Engine (Monthly)'!$C$4:$C$603,$A10)) | Q10: =IF($B10=0,"",SUMIFS('Engine (Monthly)'!$CI$4:$CI$603,'Engine (Monthly)'!$C$4:$C$603,$A10)) | R10: =IF($B10=0,"",SUMIFS('Engine (Monthly)'!$CH$4:$CH$603,'Engine (Monthly)'!$C$4:$C$603,$A10)) | S10: =IF($B10=0,"",SUMIFS('Engine (Monthly)'!$CL$4:$CL$603,'Engine (Monthly)'!$C$4:$C$603,$A10)) | T10: =IF($B10=0,"",INDEX('Engine (Monthly)'!$CQ$3:$CQ$603,MIN($A10*12,HorizonM)+1)) | U10: =IF($B10=0,"",$C10+$I10+$O10) | V10: =IF($B10=0,"",$D10+$J10+$P10) | W10: =IF($B10=0,"",$E10+$K10+$Q10) | X10: =IF($B10=0,"",$F10+$L10+$R10) | Y10: =IF($B10=0,"",$G10+$M10+$S10) | Z10: =IF($B10=0,"",'Tax Estimate'!$S10) | AA10: =IF($B10=0,"",$H10+$N10+$T10) | AB10: =IF($B10=0,"",SUMIFS('Engine (Monthly)'!$CY$4:$CY$603,'Engine (Monthly)'!$C$4:$C$603,"<="&$A10)) | AC10: =IF($B10=0,"",SUMIFS('Engine (Monthly)'!$CZ$4:$CZ$603,'Engine (Monthly)'!$C$4:$C$603,"<="&$A10)) | AD10: =IF($B10=0,"",SUMIFS('Engine (Monthly)'!$DA$4:$DA$603,'Engine (Monthly)'!$C$4:$C$603,"<="&$A10)) | AE10: =IF($B10=0,"",SUMIFS('Engine (Monthly)'!$CV$4:$CV$603,'Engine (Monthly)'!$C$4:$C$603,"<="&$A10)) | AF10: =IF($B10=0,"",IF(COUNTIFS('Engine (Monthly)'!$C$4:$C$603,$A10,'Engine (Monthly)'!$DB$4:$DB$603,1)>0,"⚠ shortfall","OK"))
A11: 8 | B11: =IF($A11<=HorizonY,1,0) | C11: =IF($B11=0,"",INDEX('Engine (Monthly)'!$AI$3:$AI$603,MIN(($A11-1)*12,HorizonM)+1)) | D11: =IF($B11=0,"",SUMIFS('Engine (Monthly)'!$X$4:$X$603,'Engine (Monthly)'!$C$4:$C$603,$A11)) | E11: =IF($B11=0,"",SUMIFS('Engine (Monthly)'!$AA$4:$AA$603,'Engine (Monthly)'!$C$4:$C$603,$A11)) | F11: =IF($B11=0,"",SUMIFS('Engine (Monthly)'!$Z$4:$Z$603,'Engine (Monthly)'!$C$4:$C$603,$A11)) | G11: =IF($B11=0,"",SUMIFS('Engine (Monthly)'!$AD$4:$AD$603,'Engine (Monthly)'!$C$4:$C$603,$A11)) | H11: =IF($B11=0,"",INDEX('Engine (Monthly)'!$AI$3:$AI$603,MIN($A11*12,HorizonM)+1)) | I11: =IF($B11=0,"",INDEX('Engine (Monthly)'!$BM$3:$BM$603,MIN(($A11-1)*12,HorizonM)+1)) | J11: =IF($B11=0,"",SUMIFS('Engine (Monthly)'!$BB$4:$BB$603,'Engine (Monthly)'!$C$4:$C$603,$A11)) | K11: =IF($B11=0,"",SUMIFS('Engine (Monthly)'!$BE$4:$BE$603,'Engine (Monthly)'!$C$4:$C$603,$A11)) | L11: =IF($B11=0,"",SUMIFS('Engine (Monthly)'!$BD$4:$BD$603,'Engine (Monthly)'!$C$4:$C$603,$A11)) | M11: =IF($B11=0,"",SUMIFS('Engine (Monthly)'!$BH$4:$BH$603,'Engine (Monthly)'!$C$4:$C$603,$A11)) | N11: =IF($B11=0,"",INDEX('Engine (Monthly)'!$BM$3:$BM$603,MIN($A11*12,HorizonM)+1)) | O11: =IF($B11=0,"",INDEX('Engine (Monthly)'!$CQ$3:$CQ$603,MIN(($A11-1)*12,HorizonM)+1)) | P11: =IF($B11=0,"",SUMIFS('Engine (Monthly)'!$CF$4:$CF$603,'Engine (Monthly)'!$C$4:$C$603,$A11)) | Q11: =IF($B11=0,"",SUMIFS('Engine (Monthly)'!$CI$4:$CI$603,'Engine (Monthly)'!$C$4:$C$603,$A11)) | R11: =IF($B11=0,"",SUMIFS('Engine (Monthly)'!$CH$4:$CH$603,'Engine (Monthly)'!$C$4:$C$603,$A11)) | S11: =IF($B11=0,"",SUMIFS('Engine (Monthly)'!$CL$4:$CL$603,'Engine (Monthly)'!$C$4:$C$603,$A11)) | T11: =IF($B11=0,"",INDEX('Engine (Monthly)'!$CQ$3:$CQ$603,MIN($A11*12,HorizonM)+1)) | U11: =IF($B11=0,"",$C11+$I11+$O11) | V11: =IF($B11=0,"",$D11+$J11+$P11) | W11: =IF($B11=0,"",$E11+$K11+$Q11) | X11: =IF($B11=0,"",$F11+$L11+$R11) | Y11: =IF($B11=0,"",$G11+$M11+$S11) | Z11: =IF($B11=0,"",'Tax Estimate'!$S11) | AA11: =IF($B11=0,"",$H11+$N11+$T11) | AB11: =IF($B11=0,"",SUMIFS('Engine (Monthly)'!$CY$4:$CY$603,'Engine (Monthly)'!$C$4:$C$603,"<="&$A11)) | AC11: =IF($B11=0,"",SUMIFS('Engine (Monthly)'!$CZ$4:$CZ$603,'Engine (Monthly)'!$C$4:$C$603,"<="&$A11)) | AD11: =IF($B11=0,"",SUMIFS('Engine (Monthly)'!$DA$4:$DA$603,'Engine (Monthly)'!$C$4:$C$603,"<="&$A11)) | AE11: =IF($B11=0,"",SUMIFS('Engine (Monthly)'!$CV$4:$CV$603,'Engine (Monthly)'!$C$4:$C$603,"<="&$A11)) | AF11: =IF($B11=0,"",IF(COUNTIFS('Engine (Monthly)'!$C$4:$C$603,$A11,'Engine (Monthly)'!$DB$4:$DB$603,1)>0,"⚠ shortfall","OK"))
A12: 9 | B12: =IF($A12<=HorizonY,1,0) | C12: =IF($B12=0,"",INDEX('Engine (Monthly)'!$AI$3:$AI$603,MIN(($A12-1)*12,HorizonM)+1)) | D12: =IF($B12=0,"",SUMIFS('Engine (Monthly)'!$X$4:$X$603,'Engine (Monthly)'!$C$4:$C$603,$A12)) | E12: =IF($B12=0,"",SUMIFS('Engine (Monthly)'!$AA$4:$AA$603,'Engine (Monthly)'!$C$4:$C$603,$A12)) | F12: =IF($B12=0,"",SUMIFS('Engine (Monthly)'!$Z$4:$Z$603,'Engine (Monthly)'!$C$4:$C$603,$A12)) | G12: =IF($B12=0,"",SUMIFS('Engine (Monthly)'!$AD$4:$AD$603,'Engine (Monthly)'!$C$4:$C$603,$A12)) | H12: =IF($B12=0,"",INDEX('Engine (Monthly)'!$AI$3:$AI$603,MIN($A12*12,HorizonM)+1)) | I12: =IF($B12=0,"",INDEX('Engine (Monthly)'!$BM$3:$BM$603,MIN(($A12-1)*12,HorizonM)+1)) | J12: =IF($B12=0,"",SUMIFS('Engine (Monthly)'!$BB$4:$BB$603,'Engine (Monthly)'!$C$4:$C$603,$A12)) | K12: =IF($B12=0,"",SUMIFS('Engine (Monthly)'!$BE$4:$BE$603,'Engine (Monthly)'!$C$4:$C$603,$A12)) | L12: =IF($B12=0,"",SUMIFS('Engine (Monthly)'!$BD$4:$BD$603,'Engine (Monthly)'!$C$4:$C$603,$A12)) | M12: =IF($B12=0,"",SUMIFS('Engine (Monthly)'!$BH$4:$BH$603,'Engine (Monthly)'!$C$4:$C$603,$A12)) | N12: =IF($B12=0,"",INDEX('Engine (Monthly)'!$BM$3:$BM$603,MIN($A12*12,HorizonM)+1)) | O12: =IF($B12=0,"",INDEX('Engine (Monthly)'!$CQ$3:$CQ$603,MIN(($A12-1)*12,HorizonM)+1)) | P12: =IF($B12=0,"",SUMIFS('Engine (Monthly)'!$CF$4:$CF$603,'Engine (Monthly)'!$C$4:$C$603,$A12)) | Q12: =IF($B12=0,"",SUMIFS('Engine (Monthly)'!$CI$4:$CI$603,'Engine (Monthly)'!$C$4:$C$603,$A12)) | R12: =IF($B12=0,"",SUMIFS('Engine (Monthly)'!$CH$4:$CH$603,'Engine (Monthly)'!$C$4:$C$603,$A12)) | S12: =IF($B12=0,"",SUMIFS('Engine (Monthly)'!$CL$4:$CL$603,'Engine (Monthly)'!$C$4:$C$603,$A12)) | T12: =IF($B12=0,"",INDEX('Engine (Monthly)'!$CQ$3:$CQ$603,MIN($A12*12,HorizonM)+1)) | U12: =IF($B12=0,"",$C12+$I12+$O12) | V12: =IF($B12=0,"",$D12+$J12+$P12) | W12: =IF($B12=0,"",$E12+$K12+$Q12) | X12: =IF($B12=0,"",$F12+$L12+$R12) | Y12: =IF($B12=0,"",$G12+$M12+$S12) | Z12: =IF($B12=0,"",'Tax Estimate'!$S12) | AA12: =IF($B12=0,"",$H12+$N12+$T12) | AB12: =IF($B12=0,"",SUMIFS('Engine (Monthly)'!$CY$4:$CY$603,'Engine (Monthly)'!$C$4:$C$603,"<="&$A12)) | AC12: =IF($B12=0,"",SUMIFS('Engine (Monthly)'!$CZ$4:$CZ$603,'Engine (Monthly)'!$C$4:$C$603,"<="&$A12)) | AD12: =IF($B12=0,"",SUMIFS('Engine (Monthly)'!$DA$4:$DA$603,'Engine (Monthly)'!$C$4:$C$603,"<="&$A12)) | AE12: =IF($B12=0,"",SUMIFS('Engine (Monthly)'!$CV$4:$CV$603,'Engine (Monthly)'!$C$4:$C$603,"<="&$A12)) | AF12: =IF($B12=0,"",IF(COUNTIFS('Engine (Monthly)'!$C$4:$C$603,$A12,'Engine (Monthly)'!$DB$4:$DB$603,1)>0,"⚠ shortfall","OK"))
A13: 10 | B13: =IF($A13<=HorizonY,1,0) | C13: =IF($B13=0,"",INDEX('Engine (Monthly)'!$AI$3:$AI$603,MIN(($A13-1)*12,HorizonM)+1)) | D13: =IF($B13=0,"",SUMIFS('Engine (Monthly)'!$X$4:$X$603,'Engine (Monthly)'!$C$4:$C$603,$A13)) | E13: =IF($B13=0,"",SUMIFS('Engine (Monthly)'!$AA$4:$AA$603,'Engine (Monthly)'!$C$4:$C$603,$A13)) | F13: =IF($B13=0,"",SUMIFS('Engine (Monthly)'!$Z$4:$Z$603,'Engine (Monthly)'!$C$4:$C$603,$A13)) | G13: =IF($B13=0,"",SUMIFS('Engine (Monthly)'!$AD$4:$AD$603,'Engine (Monthly)'!$C$4:$C$603,$A13)) | H13: =IF($B13=0,"",INDEX('Engine (Monthly)'!$AI$3:$AI$603,MIN($A13*12,HorizonM)+1)) | I13: =IF($B13=0,"",INDEX('Engine (Monthly)'!$BM$3:$BM$603,MIN(($A13-1)*12,HorizonM)+1)) | J13: =IF($B13=0,"",SUMIFS('Engine (Monthly)'!$BB$4:$BB$603,'Engine (Monthly)'!$C$4:$C$603,$A13)) | K13: =IF($B13=0,"",SUMIFS('Engine (Monthly)'!$BE$4:$BE$603,'Engine (Monthly)'!$C$4:$C$603,$A13)) | L13: =IF($B13=0,"",SUMIFS('Engine (Monthly)'!$BD$4:$BD$603,'Engine (Monthly)'!$C$4:$C$603,$A13)) | M13: =IF($B13=0,"",SUMIFS('Engine (Monthly)'!$BH$4:$BH$603,'Engine (Monthly)'!$C$4:$C$603,$A13)) | N13: =IF($B13=0,"",INDEX('Engine (Monthly)'!$BM$3:$BM$603,MIN($A13*12,HorizonM)+1)) | O13: =IF($B13=0,"",INDEX('Engine (Monthly)'!$CQ$3:$CQ$603,MIN(($A13-1)*12,HorizonM)+1)) | P13: =IF($B13=0,"",SUMIFS('Engine (Monthly)'!$CF$4:$CF$603,'Engine (Monthly)'!$C$4:$C$603,$A13)) | Q13: =IF($B13=0,"",SUMIFS('Engine (Monthly)'!$CI$4:$CI$603,'Engine (Monthly)'!$C$4:$C$603,$A13)) | R13: =IF($B13=0,"",SUMIFS('Engine (Monthly)'!$CH$4:$CH$603,'Engine (Monthly)'!$C$4:$C$603,$A13)) | S13: =IF($B13=0,"",SUMIFS('Engine (Monthly)'!$CL$4:$CL$603,'Engine (Monthly)'!$C$4:$C$603,$A13)) | T13: =IF($B13=0,"",INDEX('Engine (Monthly)'!$CQ$3:$CQ$603,MIN($A13*12,HorizonM)+1)) | U13: =IF($B13=0,"",$C13+$I13+$O13) | V13: =IF($B13=0,"",$D13+$J13+$P13) | W13: =IF($B13=0,"",$E13+$K13+$Q13) | X13: =IF($B13=0,"",$F13+$L13+$R13) | Y13: =IF($B13=0,"",$G13+$M13+$S13) | Z13: =IF($B13=0,"",'Tax Estimate'!$S13) | AA13: =IF($B13=0,"",$H13+$N13+$T13) | AB13: =IF($B13=0,"",SUMIFS('Engine (Monthly)'!$CY$4:$CY$603,'Engine (Monthly)'!$C$4:$C$603,"<="&$A13)) | AC13: =IF($B13=0,"",SUMIFS('Engine (Monthly)'!$CZ$4:$CZ$603,'Engine (Monthly)'!$C$4:$C$603,"<="&$A13)) | AD13: =IF($B13=0,"",SUMIFS('Engine (Monthly)'!$DA$4:$DA$603,'Engine (Monthly)'!$C$4:$C$603,"<="&$A13)) | AE13: =IF($B13=0,"",SUMIFS('Engine (Monthly)'!$CV$4:$CV$603,'Engine (Monthly)'!$C$4:$C$603,"<="&$A13)) | AF13: =IF($B13=0,"",IF(COUNTIFS('Engine (Monthly)'!$C$4:$C$603,$A13,'Engine (Monthly)'!$DB$4:$DB$603,1)>0,"⚠ shortfall","OK"))
A14: 11 | B14: =IF($A14<=HorizonY,1,0) | C14: =IF($B14=0,"",INDEX('Engine (Monthly)'!$AI$3:$AI$603,MIN(($A14-1)*12,HorizonM)+1)) | D14: =IF($B14=0,"",SUMIFS('Engine (Monthly)'!$X$4:$X$603,'Engine (Monthly)'!$C$4:$C$603,$A14)) | E14: =IF($B14=0,"",SUMIFS('Engine (Monthly)'!$AA$4:$AA$603,'Engine (Monthly)'!$C$4:$C$603,$A14)) | F14: =IF($B14=0,"",SUMIFS('Engine (Monthly)'!$Z$4:$Z$603,'Engine (Monthly)'!$C$4:$C$603,$A14)) | G14: =IF($B14=0,"",SUMIFS('Engine (Monthly)'!$AD$4:$AD$603,'Engine (Monthly)'!$C$4:$C$603,$A14)) | H14: =IF($B14=0,"",INDEX('Engine (Monthly)'!$AI$3:$AI$603,MIN($A14*12,HorizonM)+1)) | I14: =IF($B14=0,"",INDEX('Engine (Monthly)'!$BM$3:$BM$603,MIN(($A14-1)*12,HorizonM)+1)) | J14: =IF($B14=0,"",SUMIFS('Engine (Monthly)'!$BB$4:$BB$603,'Engine (Monthly)'!$C$4:$C$603,$A14)) | K14: =IF($B14=0,"",SUMIFS('Engine (Monthly)'!$BE$4:$BE$603,'Engine (Monthly)'!$C$4:$C$603,$A14)) | L14: =IF($B14=0,"",SUMIFS('Engine (Monthly)'!$BD$4:$BD$603,'Engine (Monthly)'!$C$4:$C$603,$A14)) | M14: =IF($B14=0,"",SUMIFS('Engine (Monthly)'!$BH$4:$BH$603,'Engine (Monthly)'!$C$4:$C$603,$A14)) | N14: =IF($B14=0,"",INDEX('Engine (Monthly)'!$BM$3:$BM$603,MIN($A14*12,HorizonM)+1)) | O14: =IF($B14=0,"",INDEX('Engine (Monthly)'!$CQ$3:$CQ$603,MIN(($A14-1)*12,HorizonM)+1)) | P14: =IF($B14=0,"",SUMIFS('Engine (Monthly)'!$CF$4:$CF$603,'Engine (Monthly)'!$C$4:$C$603,$A14)) | Q14: =IF($B14=0,"",SUMIFS('Engine (Monthly)'!$CI$4:$CI$603,'Engine (Monthly)'!$C$4:$C$603,$A14)) | R14: =IF($B14=0,"",SUMIFS('Engine (Monthly)'!$CH$4:$CH$603,'Engine (Monthly)'!$C$4:$C$603,$A14)) | S14: =IF($B14=0,"",SUMIFS('Engine (Monthly)'!$CL$4:$CL$603,'Engine (Monthly)'!$C$4:$C$603,$A14)) | T14: =IF($B14=0,"",INDEX('Engine (Monthly)'!$CQ$3:$CQ$603,MIN($A14*12,HorizonM)+1)) | U14: =IF($B14=0,"",$C14+$I14+$O14) | V14: =IF($B14=0,"",$D14+$J14+$P14) | W14: =IF($B14=0,"",$E14+$K14+$Q14) | X14: =IF($B14=0,"",$F14+$L14+$R14) | Y14: =IF($B14=0,"",$G14+$M14+$S14) | Z14: =IF($B14=0,"",'Tax Estimate'!$S14) | AA14: =IF($B14=0,"",$H14+$N14+$T14) | AB14: =IF($B14=0,"",SUMIFS('Engine (Monthly)'!$CY$4:$CY$603,'Engine (Monthly)'!$C$4:$C$603,"<="&$A14)) | AC14: =IF($B14=0,"",SUMIFS('Engine (Monthly)'!$CZ$4:$CZ$603,'Engine (Monthly)'!$C$4:$C$603,"<="&$A14)) | AD14: =IF($B14=0,"",SUMIFS('Engine (Monthly)'!$DA$4:$DA$603,'Engine (Monthly)'!$C$4:$C$603,"<="&$A14)) | AE14: =IF($B14=0,"",SUMIFS('Engine (Monthly)'!$CV$4:$CV$603,'Engine (Monthly)'!$C$4:$C$603,"<="&$A14)) | AF14: =IF($B14=0,"",IF(COUNTIFS('Engine (Monthly)'!$C$4:$C$603,$A14,'Engine (Monthly)'!$DB$4:$DB$603,1)>0,"⚠ shortfall","OK"))
A15: 12 | B15: =IF($A15<=HorizonY,1,0) | C15: =IF($B15=0,"",INDEX('Engine (Monthly)'!$AI$3:$AI$603,MIN(($A15-1)*12,HorizonM)+1)) | D15: =IF($B15=0,"",SUMIFS('Engine (Monthly)'!$X$4:$X$603,'Engine (Monthly)'!$C$4:$C$603,$A15)) | E15: =IF($B15=0,"",SUMIFS('Engine (Monthly)'!$AA$4:$AA$603,'Engine (Monthly)'!$C$4:$C$603,$A15)) | F15: =IF($B15=0,"",SUMIFS('Engine (Monthly)'!$Z$4:$Z$603,'Engine (Monthly)'!$C$4:$C$603,$A15)) | G15: =IF($B15=0,"",SUMIFS('Engine (Monthly)'!$AD$4:$AD$603,'Engine (Monthly)'!$C$4:$C$603,$A15)) | H15: =IF($B15=0,"",INDEX('Engine (Monthly)'!$AI$3:$AI$603,MIN($A15*12,HorizonM)+1)) | I15: =IF($B15=0,"",INDEX('Engine (Monthly)'!$BM$3:$BM$603,MIN(($A15-1)*12,HorizonM)+1)) | J15: =IF($B15=0,"",SUMIFS('Engine (Monthly)'!$BB$4:$BB$603,'Engine (Monthly)'!$C$4:$C$603,$A15)) | K15: =IF($B15=0,"",SUMIFS('Engine (Monthly)'!$BE$4:$BE$603,'Engine (Monthly)'!$C$4:$C$603,$A15)) | L15: =IF($B15=0,"",SUMIFS('Engine (Monthly)'!$BD$4:$BD$603,'Engine (Monthly)'!$C$4:$C$603,$A15)) | M15: =IF($B15=0,"",SUMIFS('Engine (Monthly)'!$BH$4:$BH$603,'Engine (Monthly)'!$C$4:$C$603,$A15)) | N15: =IF($B15=0,"",INDEX('Engine (Monthly)'!$BM$3:$BM$603,MIN($A15*12,HorizonM)+1)) | O15: =IF($B15=0,"",INDEX('Engine (Monthly)'!$CQ$3:$CQ$603,MIN(($A15-1)*12,HorizonM)+1)) | P15: =IF($B15=0,"",SUMIFS('Engine (Monthly)'!$CF$4:$CF$603,'Engine (Monthly)'!$C$4:$C$603,$A15)) | Q15: =IF($B15=0,"",SUMIFS('Engine (Monthly)'!$CI$4:$CI$603,'Engine (Monthly)'!$C$4:$C$603,$A15)) | R15: =IF($B15=0,"",SUMIFS('Engine (Monthly)'!$CH$4:$CH$603,'Engine (Monthly)'!$C$4:$C$603,$A15)) | S15: =IF($B15=0,"",SUMIFS('Engine (Monthly)'!$CL$4:$CL$603,'Engine (Monthly)'!$C$4:$C$603,$A15)) | T15: =IF($B15=0,"",INDEX('Engine (Monthly)'!$CQ$3:$CQ$603,MIN($A15*12,HorizonM)+1)) | U15: =IF($B15=0,"",$C15+$I15+$O15) | V15: =IF($B15=0,"",$D15+$J15+$P15) | W15: =IF($B15=0,"",$E15+$K15+$Q15) | X15: =IF($B15=0,"",$F15+$L15+$R15) | Y15: =IF($B15=0,"",$G15+$M15+$S15) | Z15: =IF($B15=0,"",'Tax Estimate'!$S15) | AA15: =IF($B15=0,"",$H15+$N15+$T15) | AB15: =IF($B15=0,"",SUMIFS('Engine (Monthly)'!$CY$4:$CY$603,'Engine (Monthly)'!$C$4:$C$603,"<="&$A15)) | AC15: =IF($B15=0,"",SUMIFS('Engine (Monthly)'!$CZ$4:$CZ$603,'Engine (Monthly)'!$C$4:$C$603,"<="&$A15)) | AD15: =IF($B15=0,"",SUMIFS('Engine (Monthly)'!$DA$4:$DA$603,'Engine (Monthly)'!$C$4:$C$603,"<="&$A15)) | AE15: =IF($B15=0,"",SUMIFS('Engine (Monthly)'!$CV$4:$CV$603,'Engine (Monthly)'!$C$4:$C$603,"<="&$A15)) | AF15: =IF($B15=0,"",IF(COUNTIFS('Engine (Monthly)'!$C$4:$C$603,$A15,'Engine (Monthly)'!$DB$4:$DB$603,1)>0,"⚠ shortfall","OK"))
... A53: 50 | B53: =IF($A53<=HorizonY,1,0) | C53: =IF($B53=0,"",INDEX('Engine (Monthly)'!$AI$3:$AI$603,MIN(($A53-1)*12,HorizonM)+1)) | D53: =IF($B53=0,"",SUMIFS('Engine (Monthly)'!$X$4:$X$603,'Engine (Monthly)'!$C$4:$C$603,$A53)) | E53: =IF($B53=0,"",SUMIFS('Engine (Monthly)'!$AA$4:$AA$603,'Engine (Monthly)'!$C$4:$C$603,$A53)) | F53: =IF($B53=0,"",SUMIFS('Engine (Monthly)'!$Z$4:$Z$603,'Engine (Monthly)'!$C$4:$C$603,$A53)) | G53: =IF($B53=0,"",SUMIFS('Engine (Monthly)'!$AD$4:$AD$603,'Engine (Monthly)'!$C$4:$C$603,$A53)) | H53: =IF($B53=0,"",INDEX('Engine (Monthly)'!$AI$3:$AI$603,MIN($A53*12,HorizonM)+1)) | I53: =IF($B53=0,"",INDEX('Engine (Monthly)'!$BM$3:$BM$603,MIN(($A53-1)*12,HorizonM)+1)) | J53: =IF($B53=0,"",SUMIFS('Engine (Monthly)'!$BB$4:$BB$603,'Engine (Monthly)'!$C$4:$C$603,$A53)) | K53: =IF($B53=0,"",SUMIFS('Engine (Monthly)'!$BE$4:$BE$603,'Engine (Monthly)'!$C$4:$C$603,$A53)) | L53: =IF($B53=0,"",SUMIFS('Engine (Monthly)'!$BD$4:$BD$603,'Engine (Monthly)'!$C$4:$C$603,$A53)) | M53: =IF($B53=0,"",SUMIFS('Engine (Monthly)'!$BH$4:$BH$603,'Engine (Monthly)'!$C$4:$C$603,$A53)) | N53: =IF($B53=0,"",INDEX('Engine (Monthly)'!$BM$3:$BM$603,MIN($A53*12,HorizonM)+1)) | O53: =IF($B53=0,"",INDEX('Engine (Monthly)'!$CQ$3:$CQ$603,MIN(($A53-1)*12,HorizonM)+1)) | P53: =IF($B53=0,"",SUMIFS('Engine (Monthly)'!$CF$4:$CF$603,'Engine (Monthly)'!$C$4:$C$603,$A53)) | Q53: =IF($B53=0,"",SUMIFS('Engine (Monthly)'!$CI$4:$CI$603,'Engine (Monthly)'!$C$4:$C$603,$A53)) | R53: =IF($B53=0,"",SUMIFS('Engine (Monthly)'!$CH$4:$CH$603,'Engine (Monthly)'!$C$4:$C$603,$A53)) | S53: =IF($B53=0,"",SUMIFS('Engine (Monthly)'!$CL$4:$CL$603,'Engine (Monthly)'!$C$4:$C$603,$A53)) | T53: =IF($B53=0,"",INDEX('Engine (Monthly)'!$CQ$3:$CQ$603,MIN($A53*12,HorizonM)+1)) | U53: =IF($B53=0,"",$C53+$I53+$O53) | V53: =IF($B53=0,"",$D53+$J53+$P53) | W53: =IF($B53=0,"",$E53+$K53+$Q53) | X53: =IF($B53=0,"",$F53+$L53+$R53) | Y53: =IF($B53=0,"",$G53+$M53+$S53) | Z53: =IF($B53=0,"",'Tax Estimate'!$S53) | AA53: =IF($B53=0,"",$H53+$N53+$T53) | AB53: =IF($B53=0,"",SUMIFS('Engine (Monthly)'!$CY$4:$CY$603,'Engine (Monthly)'!$C$4:$C$603,"<="&$A53)) | AC53: =IF($B53=0,"",SUMIFS('Engine (Monthly)'!$CZ$4:$CZ$603,'Engine (Monthly)'!$C$4:$C$603,"<="&$A53)) | AD53: =IF($B53=0,"",SUMIFS('Engine (Monthly)'!$DA$4:$DA$603,'Engine (Monthly)'!$C$4:$C$603,"<="&$A53)) | AE53: =IF($B53=0,"",SUMIFS('Engine (Monthly)'!$CV$4:$CV$603,'Engine (Monthly)'!$C$4:$C$603,"<="&$A53)) | AF53: =IF($B53=0,"",IF(COUNTIFS('Engine (Monthly)'!$C$4:$C$603,$A53,'Engine (Monthly)'!$DB$4:$DB$603,1)>0,"⚠ shortfall","OK"))

Sheet Tax Estimate
A1: Tax Estimate — CRA federal + Ontario, tax year 2026 rules | V1: Tax on other income alone: | X1: =MAX(0,SUMPRODUCT((N(OtherInc)>FedThr)*((N(OtherInc))-FedThr)*FedDlt)-(FedBPAMax-(FedBPAMax-FedBPAMin)*MIN(1,MAX(0,((N(OtherInc))-FedPhLow)/(FedPhHigh-FedPhLow))))*FedLowRate) | Y1: =MAX(0,SUMPRODUCT((N(OtherInc)>ONThr)*((N(OtherInc))-ONThr)*ONDlt)-ONBPA*ONLowRate) | Z1: =$X$1+$Y$1+ONSurR1*MAX(0,$Y$1-ONSur1)+ONSurR2*MAX(0,$Y$1-ONSur2)
A2: Standalone = portfolio is the only income. Stacked = portfolio on top of other income (shows the incremental tax only). Excluded by design: AMT, Ontario Health Premium, OAS clawback, CPP/EI — a large single-year sale may trigger AMT; confirm with an accountant.
A3: Year | B3: · | C3: Eligible dividends (NR) | D3: Non-eligible dividends (NR) | E3: Foreign / interest (NR) | F3: Realized capital gains | G3: RRSP/RRIF withdrawals | H3: TFSA withdrawals (tax-free) | I3: Grossed-up eligible | J3: Grossed-up non-eligible | K3: Taxable income (standalone) | L3: Fed tax before credits | M3: Fed BPA | N3: Federal tax | O3: ON tax before credits | P3: ON basic tax | Q3: ON surtax | R3: Ontario tax | S3: TOTAL TAX (standalone) | T3: Effective rate on cash income | U3: Taxable income (stacked) | V3: Stk fed before credits | W3: Stk fed BPA | X3: Stk federal tax | Y3: Stk ON before credits | Z3: Stk ON basic | AA3: Stk ON surtax | AB3: Stk Ontario tax | AC3: Stk total (all income) | AD3: INCREMENTAL TAX (stacked view) | AE3: T·A fed | AF3: T·A ON basic | AG3: T·A total | AH3: T·B fed | AI3: T·B ON basic | AJ3: T·B total | AK3: T·C fed | AL3: T·C ON basic | AM3: T·C total | AN3: Tax: interest/foreign | AO3: Tax: RRSP withdrawals | AP3: Tax: capital gains | AQ3: Tax: dividends (net of credits)
A4: 1 | B4: =IF($A4<=HorizonY,1,0) | C4: =SUMIFS('Engine (Monthly)'!$CR$4:$CR$603,'Engine (Monthly)'!$C$4:$C$603,$A4) | D4: =SUMIFS('Engine (Monthly)'!$CS$4:$CS$603,'Engine (Monthly)'!$C$4:$C$603,$A4) | E4: =SUMIFS('Engine (Monthly)'!$CT$4:$CT$603,'Engine (Monthly)'!$C$4:$C$603,$A4) | F4: =MAX(0,SUMIFS('Engine (Monthly)'!$CV$4:$CV$603,'Engine (Monthly)'!$C$4:$C$603,$A4)) | G4: =SUMIFS('Engine (Monthly)'!$CL$4:$CL$603,'Engine (Monthly)'!$C$4:$C$603,$A4) | H4: =SUMIFS('Engine (Monthly)'!$BH$4:$BH$603,'Engine (Monthly)'!$C$4:$C$603,$A4) | I4: =$C4*(1+GUE) | J4: =$D4*(1+GUN) | K4: =$I4+$J4+$E4+CGInc*$F4+$G4 | L4: =SUMPRODUCT(($K4>FedThr)*(($K4)-FedThr)*FedDlt) | M4: =(FedBPAMax-(FedBPAMax-FedBPAMin)*MIN(1,MAX(0,(($K4)-FedPhLow)/(FedPhHigh-FedPhLow)))) | N4: =MAX(0,$L4-$M4*FedLowRate-$I4*FDTCE-$J4*FDTCN) | O4: =SUMPRODUCT(($K4>ONThr)*(($K4)-ONThr)*ONDlt) | P4: =MAX(0,$O4-ONBPA*ONLowRate) | Q4: =ONSurR1*MAX(0,$P4-ONSur1)+ONSurR2*MAX(0,$P4-ONSur2) | R4: =MAX(0,$P4+$Q4-$I4*ODTCE-$J4*ODTCN) | S4: =$N4+$R4 | T4: =IF($C4+$D4+$E4+$F4+$G4>0,$S4/($C4+$D4+$E4+$F4+$G4),0) | U4: =$K4+N(OtherInc) | V4: =SUMPRODUCT(($U4>FedThr)*(($U4)-FedThr)*FedDlt) | W4: =(FedBPAMax-(FedBPAMax-FedBPAMin)*MIN(1,MAX(0,(($U4)-FedPhLow)/(FedPhHigh-FedPhLow)))) | X4: =MAX(0,$V4-$W4*FedLowRate-$I4*FDTCE-$J4*FDTCN) | Y4: =SUMPRODUCT(($U4>ONThr)*(($U4)-ONThr)*ONDlt) | Z4: =MAX(0,$Y4-ONBPA*ONLowRate) | AA4: =ONSurR1*MAX(0,$Z4-ONSur1)+ONSurR2*MAX(0,$Z4-ONSur2) | AB4: =MAX(0,$Z4+$AA4-$I4*ODTCE-$J4*ODTCN) | AC4: =$X4+$AB4 | AD4: =IF($B4=0,0,$AC4-BaseTaxTotal) | AE4: =MAX(0,SUMPRODUCT((N(OtherInc)+$E4>FedThr)*((N(OtherInc)+$E4)-FedThr)*FedDlt)-(FedBPAMax-(FedBPAMax-FedBPAMin)*MIN(1,MAX(0,((N(OtherInc)+$E4)-FedPhLow)/(FedPhHigh-FedPhLow))))*FedLowRate) | AF4: =MAX(0,SUMPRODUCT((N(OtherInc)+$E4>ONThr)*((N(OtherInc)+$E4)-ONThr)*ONDlt)-ONBPA*ONLowRate) | AG4: =$AE4+$AF4+ONSurR1*MAX(0,$AF4-ONSur1)+ONSurR2*MAX(0,$AF4-ONSur2) | AH4: =MAX(0,SUMPRODUCT((N(OtherInc)+$E4+$G4>FedThr)*((N(OtherInc)+$E4+$G4)-FedThr)*FedDlt)-(FedBPAMax-(FedBPAMax-FedBPAMin)*MIN(1,MAX(0,((N(OtherInc)+$E4+$G4)-FedPhLow)/(FedPhHigh-FedPhLow))))*FedLowRate) | AI4: =MAX(0,SUMPRODUCT((N(OtherInc)+$E4+$G4>ONThr)*((N(OtherInc)+$E4+$G4)-ONThr)*ONDlt)-ONBPA*ONLowRate) | AJ4: =$AH4+$AI4+ONSurR1*MAX(0,$AI4-ONSur1)+ONSurR2*MAX(0,$AI4-ONSur2) | AK4: =MAX(0,SUMPRODUCT((N(OtherInc)+$E4+$G4+CGInc*$F4>FedThr)*((N(OtherInc)+$E4+$G4+CGInc*$F4)-FedThr)*FedDlt)-(FedBPAMax-(FedBPAMax-FedBPAMin)*MIN(1,MAX(0,((N(OtherInc)+$E4+$G4+CGInc*$F4)-FedPhLow)/(FedPhHigh-FedPhLow))))*FedLowRate) | AL4: =MAX(0,SUMPRODUCT((N(OtherInc)+$E4+$G4+CGInc*$F4>ONThr)*((N(OtherInc)+$E4+$G4+CGInc*$F4)-ONThr)*ONDlt)-ONBPA*ONLowRate) | AM4: =$AK4+$AL4+ONSurR1*MAX(0,$AL4-ONSur1)+ONSurR2*MAX(0,$AL4-ONSur2) | AN4: =IF($B4=0,0,$AG4-BaseTaxTotal) | AO4: =$AJ4-$AG4 | AP4: =$AM4-$AJ4 | AQ4: =$AC4-$AM4
A5: 2 | B5: =IF($A5<=HorizonY,1,0) | C5: =SUMIFS('Engine (Monthly)'!$CR$4:$CR$603,'Engine (Monthly)'!$C$4:$C$603,$A5) | D5: =SUMIFS('Engine (Monthly)'!$CS$4:$CS$603,'Engine (Monthly)'!$C$4:$C$603,$A5) | E5: =SUMIFS('Engine (Monthly)'!$CT$4:$CT$603,'Engine (Monthly)'!$C$4:$C$603,$A5) | F5: =MAX(0,SUMIFS('Engine (Monthly)'!$CV$4:$CV$603,'Engine (Monthly)'!$C$4:$C$603,$A5)) | G5: =SUMIFS('Engine (Monthly)'!$CL$4:$CL$603,'Engine (Monthly)'!$C$4:$C$603,$A5) | H5: =SUMIFS('Engine (Monthly)'!$BH$4:$BH$603,'Engine (Monthly)'!$C$4:$C$603,$A5) | I5: =$C5*(1+GUE) | J5: =$D5*(1+GUN) | K5: =$I5+$J5+$E5+CGInc*$F5+$G5 | L5: =SUMPRODUCT(($K5>FedThr)*(($K5)-FedThr)*FedDlt) | M5: =(FedBPAMax-(FedBPAMax-FedBPAMin)*MIN(1,MAX(0,(($K5)-FedPhLow)/(FedPhHigh-FedPhLow)))) | N5: =MAX(0,$L5-$M5*FedLowRate-$I5*FDTCE-$J5*FDTCN) | O5: =SUMPRODUCT(($K5>ONThr)*(($K5)-ONThr)*ONDlt) | P5: =MAX(0,$O5-ONBPA*ONLowRate) | Q5: =ONSurR1*MAX(0,$P5-ONSur1)+ONSurR2*MAX(0,$P5-ONSur2) | R5: =MAX(0,$P5+$Q5-$I5*ODTCE-$J5*ODTCN) | S5: =$N5+$R5 | T5: =IF($C5+$D5+$E5+$F5+$G5>0,$S5/($C5+$D5+$E5+$F5+$G5),0) | U5: =$K5+N(OtherInc) | V5: =SUMPRODUCT(($U5>FedThr)*(($U5)-FedThr)*FedDlt) | W5: =(FedBPAMax-(FedBPAMax-FedBPAMin)*MIN(1,MAX(0,(($U5)-FedPhLow)/(FedPhHigh-FedPhLow)))) | X5: =MAX(0,$V5-$W5*FedLowRate-$I5*FDTCE-$J5*FDTCN) | Y5: =SUMPRODUCT(($U5>ONThr)*(($U5)-ONThr)*ONDlt) | Z5: =MAX(0,$Y5-ONBPA*ONLowRate) | AA5: =ONSurR1*MAX(0,$Z5-ONSur1)+ONSurR2*MAX(0,$Z5-ONSur2) | AB5: =MAX(0,$Z5+$AA5-$I5*ODTCE-$J5*ODTCN) | AC5: =$X5+$AB5 | AD5: =IF($B5=0,0,$AC5-BaseTaxTotal) | AE5: =MAX(0,SUMPRODUCT((N(OtherInc)+$E5>FedThr)*((N(OtherInc)+$E5)-FedThr)*FedDlt)-(FedBPAMax-(FedBPAMax-FedBPAMin)*MIN(1,MAX(0,((N(OtherInc)+$E5)-FedPhLow)/(FedPhHigh-FedPhLow))))*FedLowRate) | AF5: =MAX(0,SUMPRODUCT((N(OtherInc)+$E5>ONThr)*((N(OtherInc)+$E5)-ONThr)*ONDlt)-ONBPA*ONLowRate) | AG5: =$AE5+$AF5+ONSurR1*MAX(0,$AF5-ONSur1)+ONSurR2*MAX(0,$AF5-ONSur2) | AH5: =MAX(0,SUMPRODUCT((N(OtherInc)+$E5+$G5>FedThr)*((N(OtherInc)+$E5+$G5)-FedThr)*FedDlt)-(FedBPAMax-(FedBPAMax-FedBPAMin)*MIN(1,MAX(0,((N(OtherInc)+$E5+$G5)-FedPhLow)/(FedPhHigh-FedPhLow))))*FedLowRate) | AI5: =MAX(0,SUMPRODUCT((N(OtherInc)+$E5+$G5>ONThr)*((N(OtherInc)+$E5+$G5)-ONThr)*ONDlt)-ONBPA*ONLowRate) | AJ5: =$AH5+$AI5+ONSurR1*MAX(0,$AI5-ONSur1)+ONSurR2*MAX(0,$AI5-ONSur2) | AK5: =MAX(0,SUMPRODUCT((N(OtherInc)+$E5+$G5+CGInc*$F5>FedThr)*((N(OtherInc)+$E5+$G5+CGInc*$F5)-FedThr)*FedDlt)-(FedBPAMax-(FedBPAMax-FedBPAMin)*MIN(1,MAX(0,((N(OtherInc)+$E5+$G5+CGInc*$F5)-FedPhLow)/(FedPhHigh-FedPhLow))))*FedLowRate) | AL5: =MAX(0,SUMPRODUCT((N(OtherInc)+$E5+$G5+CGInc*$F5>ONThr)*((N(OtherInc)+$E5+$G5+CGInc*$F5)-ONThr)*ONDlt)-ONBPA*ONLowRate) | AM5: =$AK5+$AL5+ONSurR1*MAX(0,$AL5-ONSur1)+ONSurR2*MAX(0,$AL5-ONSur2) | AN5: =IF($B5=0,0,$AG5-BaseTaxTotal) | AO5: =$AJ5-$AG5 | AP5: =$AM5-$AJ5 | AQ5: =$AC5-$AM5
A6: 3 | B6: =IF($A6<=HorizonY,1,0) | C6: =SUMIFS('Engine (Monthly)'!$CR$4:$CR$603,'Engine (Monthly)'!$C$4:$C$603,$A6) | D6: =SUMIFS('Engine (Monthly)'!$CS$4:$CS$603,'Engine (Monthly)'!$C$4:$C$603,$A6) | E6: =SUMIFS('Engine (Monthly)'!$CT$4:$CT$603,'Engine (Monthly)'!$C$4:$C$603,$A6) | F6: =MAX(0,SUMIFS('Engine (Monthly)'!$CV$4:$CV$603,'Engine (Monthly)'!$C$4:$C$603,$A6)) | G6: =SUMIFS('Engine (Monthly)'!$CL$4:$CL$603,'Engine (Monthly)'!$C$4:$C$603,$A6) | H6: =SUMIFS('Engine (Monthly)'!$BH$4:$BH$603,'Engine (Monthly)'!$C$4:$C$603,$A6) | I6: =$C6*(1+GUE) | J6: =$D6*(1+GUN) | K6: =$I6+$J6+$E6+CGInc*$F6+$G6 | L6: =SUMPRODUCT(($K6>FedThr)*(($K6)-FedThr)*FedDlt) | M6: =(FedBPAMax-(FedBPAMax-FedBPAMin)*MIN(1,MAX(0,(($K6)-FedPhLow)/(FedPhHigh-FedPhLow)))) | N6: =MAX(0,$L6-$M6*FedLowRate-$I6*FDTCE-$J6*FDTCN) | O6: =SUMPRODUCT(($K6>ONThr)*(($K6)-ONThr)*ONDlt) | P6: =MAX(0,$O6-ONBPA*ONLowRate) | Q6: =ONSurR1*MAX(0,$P6-ONSur1)+ONSurR2*MAX(0,$P6-ONSur2) | R6: =MAX(0,$P6+$Q6-$I6*ODTCE-$J6*ODTCN) | S6: =$N6+$R6 | T6: =IF($C6+$D6+$E6+$F6+$G6>0,$S6/($C6+$D6+$E6+$F6+$G6),0) | U6: =$K6+N(OtherInc) | V6: =SUMPRODUCT(($U6>FedThr)*(($U6)-FedThr)*FedDlt) | W6: =(FedBPAMax-(FedBPAMax-FedBPAMin)*MIN(1,MAX(0,(($U6)-FedPhLow)/(FedPhHigh-FedPhLow)))) | X6: =MAX(0,$V6-$W6*FedLowRate-$I6*FDTCE-$J6*FDTCN) | Y6: =SUMPRODUCT(($U6>ONThr)*(($U6)-ONThr)*ONDlt) | Z6: =MAX(0,$Y6-ONBPA*ONLowRate) | AA6: =ONSurR1*MAX(0,$Z6-ONSur1)+ONSurR2*MAX(0,$Z6-ONSur2) | AB6: =MAX(0,$Z6+$AA6-$I6*ODTCE-$J6*ODTCN) | AC6: =$X6+$AB6 | AD6: =IF($B6=0,0,$AC6-BaseTaxTotal) | AE6: =MAX(0,SUMPRODUCT((N(OtherInc)+$E6>FedThr)*((N(OtherInc)+$E6)-FedThr)*FedDlt)-(FedBPAMax-(FedBPAMax-FedBPAMin)*MIN(1,MAX(0,((N(OtherInc)+$E6)-FedPhLow)/(FedPhHigh-FedPhLow))))*FedLowRate) | AF6: =MAX(0,SUMPRODUCT((N(OtherInc)+$E6>ONThr)*((N(OtherInc)+$E6)-ONThr)*ONDlt)-ONBPA*ONLowRate) | AG6: =$AE6+$AF6+ONSurR1*MAX(0,$AF6-ONSur1)+ONSurR2*MAX(0,$AF6-ONSur2) | AH6: =MAX(0,SUMPRODUCT((N(OtherInc)+$E6+$G6>FedThr)*((N(OtherInc)+$E6+$G6)-FedThr)*FedDlt)-(FedBPAMax-(FedBPAMax-FedBPAMin)*MIN(1,MAX(0,((N(OtherInc)+$E6+$G6)-FedPhLow)/(FedPhHigh-FedPhLow))))*FedLowRate) | AI6: =MAX(0,SUMPRODUCT((N(OtherInc)+$E6+$G6>ONThr)*((N(OtherInc)+$E6+$G6)-ONThr)*ONDlt)-ONBPA*ONLowRate) | AJ6: =$AH6+$AI6+ONSurR1*MAX(0,$AI6-ONSur1)+ONSurR2*MAX(0,$AI6-ONSur2) | AK6: =MAX(0,SUMPRODUCT((N(OtherInc)+$E6+$G6+CGInc*$F6>FedThr)*((N(OtherInc)+$E6+$G6+CGInc*$F6)-FedThr)*FedDlt)-(FedBPAMax-(FedBPAMax-FedBPAMin)*MIN(1,MAX(0,((N(OtherInc)+$E6+$G6+CGInc*$F6)-FedPhLow)/(FedPhHigh-FedPhLow))))*FedLowRate) | AL6: =MAX(0,SUMPRODUCT((N(OtherInc)+$E6+$G6+CGInc*$F6>ONThr)*((N(OtherInc)+$E6+$G6+CGInc*$F6)-ONThr)*ONDlt)-ONBPA*ONLowRate) | AM6: =$AK6+$AL6+ONSurR1*MAX(0,$AL6-ONSur1)+ONSurR2*MAX(0,$AL6-ONSur2) | AN6: =IF($B6=0,0,$AG6-BaseTaxTotal) | AO6: =$AJ6-$AG6 | AP6: =$AM6-$AJ6 | AQ6: =$AC6-$AM6
A7: 4 | B7: =IF($A7<=HorizonY,1,0) | C7: =SUMIFS('Engine (Monthly)'!$CR$4:$CR$603,'Engine (Monthly)'!$C$4:$C$603,$A7) | D7: =SUMIFS('Engine (Monthly)'!$CS$4:$CS$603,'Engine (Monthly)'!$C$4:$C$603,$A7) | E7: =SUMIFS('Engine (Monthly)'!$CT$4:$CT$603,'Engine (Monthly)'!$C$4:$C$603,$A7) | F7: =MAX(0,SUMIFS('Engine (Monthly)'!$CV$4:$CV$603,'Engine (Monthly)'!$C$4:$C$603,$A7)) | G7: =SUMIFS('Engine (Monthly)'!$CL$4:$CL$603,'Engine (Monthly)'!$C$4:$C$603,$A7) | H7: =SUMIFS('Engine (Monthly)'!$BH$4:$BH$603,'Engine (Monthly)'!$C$4:$C$603,$A7) | I7: =$C7*(1+GUE) | J7: =$D7*(1+GUN) | K7: =$I7+$J7+$E7+CGInc*$F7+$G7 | L7: =SUMPRODUCT(($K7>FedThr)*(($K7)-FedThr)*FedDlt) | M7: =(FedBPAMax-(FedBPAMax-FedBPAMin)*MIN(1,MAX(0,(($K7)-FedPhLow)/(FedPhHigh-FedPhLow)))) | N7: =MAX(0,$L7-$M7*FedLowRate-$I7*FDTCE-$J7*FDTCN) | O7: =SUMPRODUCT(($K7>ONThr)*(($K7)-ONThr)*ONDlt) | P7: =MAX(0,$O7-ONBPA*ONLowRate) | Q7: =ONSurR1*MAX(0,$P7-ONSur1)+ONSurR2*MAX(0,$P7-ONSur2) | R7: =MAX(0,$P7+$Q7-$I7*ODTCE-$J7*ODTCN) | S7: =$N7+$R7 | T7: =IF($C7+$D7+$E7+$F7+$G7>0,$S7/($C7+$D7+$E7+$F7+$G7),0) | U7: =$K7+N(OtherInc) | V7: =SUMPRODUCT(($U7>FedThr)*(($U7)-FedThr)*FedDlt) | W7: =(FedBPAMax-(FedBPAMax-FedBPAMin)*MIN(1,MAX(0,(($U7)-FedPhLow)/(FedPhHigh-FedPhLow)))) | X7: =MAX(0,$V7-$W7*FedLowRate-$I7*FDTCE-$J7*FDTCN) | Y7: =SUMPRODUCT(($U7>ONThr)*(($U7)-ONThr)*ONDlt) | Z7: =MAX(0,$Y7-ONBPA*ONLowRate) | AA7: =ONSurR1*MAX(0,$Z7-ONSur1)+ONSurR2*MAX(0,$Z7-ONSur2) | AB7: =MAX(0,$Z7+$AA7-$I7*ODTCE-$J7*ODTCN) | AC7: =$X7+$AB7 | AD7: =IF($B7=0,0,$AC7-BaseTaxTotal) | AE7: =MAX(0,SUMPRODUCT((N(OtherInc)+$E7>FedThr)*((N(OtherInc)+$E7)-FedThr)*FedDlt)-(FedBPAMax-(FedBPAMax-FedBPAMin)*MIN(1,MAX(0,((N(OtherInc)+$E7)-FedPhLow)/(FedPhHigh-FedPhLow))))*FedLowRate) | AF7: =MAX(0,SUMPRODUCT((N(OtherInc)+$E7>ONThr)*((N(OtherInc)+$E7)-ONThr)*ONDlt)-ONBPA*ONLowRate) | AG7: =$AE7+$AF7+ONSurR1*MAX(0,$AF7-ONSur1)+ONSurR2*MAX(0,$AF7-ONSur2) | AH7: =MAX(0,SUMPRODUCT((N(OtherInc)+$E7+$G7>FedThr)*((N(OtherInc)+$E7+$G7)-FedThr)*FedDlt)-(FedBPAMax-(FedBPAMax-FedBPAMin)*MIN(1,MAX(0,((N(OtherInc)+$E7+$G7)-FedPhLow)/(FedPhHigh-FedPhLow))))*FedLowRate) | AI7: =MAX(0,SUMPRODUCT((N(OtherInc)+$E7+$G7>ONThr)*((N(OtherInc)+$E7+$G7)-ONThr)*ONDlt)-ONBPA*ONLowRate) | AJ7: =$AH7+$AI7+ONSurR1*MAX(0,$AI7-ONSur1)+ONSurR2*MAX(0,$AI7-ONSur2) | AK7: =MAX(0,SUMPRODUCT((N(OtherInc)+$E7+$G7+CGInc*$F7>FedThr)*((N(OtherInc)+$E7+$G7+CGInc*$F7)-FedThr)*FedDlt)-(FedBPAMax-(FedBPAMax-FedBPAMin)*MIN(1,MAX(0,((N(OtherInc)+$E7+$G7+CGInc*$F7)-FedPhLow)/(FedPhHigh-FedPhLow))))*FedLowRate) | AL7: =MAX(0,SUMPRODUCT((N(OtherInc)+$E7+$G7+CGInc*$F7>ONThr)*((N(OtherInc)+$E7+$G7+CGInc*$F7)-ONThr)*ONDlt)-ONBPA*ONLowRate) | AM7: =$AK7+$AL7+ONSurR1*MAX(0,$AL7-ONSur1)+ONSurR2*MAX(0,$AL7-ONSur2) | AN7: =IF($B7=0,0,$AG7-BaseTaxTotal) | AO7: =$AJ7-$AG7 | AP7: =$AM7-$AJ7 | AQ7: =$AC7-$AM7
A8: 5 | B8: =IF($A8<=HorizonY,1,0) | C8: =SUMIFS('Engine (Monthly)'!$CR$4:$CR$603,'Engine (Monthly)'!$C$4:$C$603,$A8) | D8: =SUMIFS('Engine (Monthly)'!$CS$4:$CS$603,'Engine (Monthly)'!$C$4:$C$603,$A8) | E8: =SUMIFS('Engine (Monthly)'!$CT$4:$CT$603,'Engine (Monthly)'!$C$4:$C$603,$A8) | F8: =MAX(0,SUMIFS('Engine (Monthly)'!$CV$4:$CV$603,'Engine (Monthly)'!$C$4:$C$603,$A8)) | G8: =SUMIFS('Engine (Monthly)'!$CL$4:$CL$603,'Engine (Monthly)'!$C$4:$C$603,$A8) | H8: =SUMIFS('Engine (Monthly)'!$BH$4:$BH$603,'Engine (Monthly)'!$C$4:$C$603,$A8) | I8: =$C8*(1+GUE) | J8: =$D8*(1+GUN) | K8: =$I8+$J8+$E8+CGInc*$F8+$G8 | L8: =SUMPRODUCT(($K8>FedThr)*(($K8)-FedThr)*FedDlt) | M8: =(FedBPAMax-(FedBPAMax-FedBPAMin)*MIN(1,MAX(0,(($K8)-FedPhLow)/(FedPhHigh-FedPhLow)))) | N8: =MAX(0,$L8-$M8*FedLowRate-$I8*FDTCE-$J8*FDTCN) | O8: =SUMPRODUCT(($K8>ONThr)*(($K8)-ONThr)*ONDlt) | P8: =MAX(0,$O8-ONBPA*ONLowRate) | Q8: =ONSurR1*MAX(0,$P8-ONSur1)+ONSurR2*MAX(0,$P8-ONSur2) | R8: =MAX(0,$P8+$Q8-$I8*ODTCE-$J8*ODTCN) | S8: =$N8+$R8 | T8: =IF($C8+$D8+$E8+$F8+$G8>0,$S8/($C8+$D8+$E8+$F8+$G8),0) | U8: =$K8+N(OtherInc) | V8: =SUMPRODUCT(($U8>FedThr)*(($U8)-FedThr)*FedDlt) | W8: =(FedBPAMax-(FedBPAMax-FedBPAMin)*MIN(1,MAX(0,(($U8)-FedPhLow)/(FedPhHigh-FedPhLow)))) | X8: =MAX(0,$V8-$W8*FedLowRate-$I8*FDTCE-$J8*FDTCN) | Y8: =SUMPRODUCT(($U8>ONThr)*(($U8)-ONThr)*ONDlt) | Z8: =MAX(0,$Y8-ONBPA*ONLowRate) | AA8: =ONSurR1*MAX(0,$Z8-ONSur1)+ONSurR2*MAX(0,$Z8-ONSur2) | AB8: =MAX(0,$Z8+$AA8-$I8*ODTCE-$J8*ODTCN) | AC8: =$X8+$AB8 | AD8: =IF($B8=0,0,$AC8-BaseTaxTotal) | AE8: =MAX(0,SUMPRODUCT((N(OtherInc)+$E8>FedThr)*((N(OtherInc)+$E8)-FedThr)*FedDlt)-(FedBPAMax-(FedBPAMax-FedBPAMin)*MIN(1,MAX(0,((N(OtherInc)+$E8)-FedPhLow)/(FedPhHigh-FedPhLow))))*FedLowRate) | AF8: =MAX(0,SUMPRODUCT((N(OtherInc)+$E8>ONThr)*((N(OtherInc)+$E8)-ONThr)*ONDlt)-ONBPA*ONLowRate) | AG8: =$AE8+$AF8+ONSurR1*MAX(0,$AF8-ONSur1)+ONSurR2*MAX(0,$AF8-ONSur2) | AH8: =MAX(0,SUMPRODUCT((N(OtherInc)+$E8+$G8>FedThr)*((N(OtherInc)+$E8+$G8)-FedThr)*FedDlt)-(FedBPAMax-(FedBPAMax-FedBPAMin)*MIN(1,MAX(0,((N(OtherInc)+$E8+$G8)-FedPhLow)/(FedPhHigh-FedPhLow))))*FedLowRate) | AI8: =MAX(0,SUMPRODUCT((N(OtherInc)+$E8+$G8>ONThr)*((N(OtherInc)+$E8+$G8)-ONThr)*ONDlt)-ONBPA*ONLowRate) | AJ8: =$AH8+$AI8+ONSurR1*MAX(0,$AI8-ONSur1)+ONSurR2*MAX(0,$AI8-ONSur2) | AK8: =MAX(0,SUMPRODUCT((N(OtherInc)+$E8+$G8+CGInc*$F8>FedThr)*((N(OtherInc)+$E8+$G8+CGInc*$F8)-FedThr)*FedDlt)-(FedBPAMax-(FedBPAMax-FedBPAMin)*MIN(1,MAX(0,((N(OtherInc)+$E8+$G8+CGInc*$F8)-FedPhLow)/(FedPhHigh-FedPhLow))))*FedLowRate) | AL8: =MAX(0,SUMPRODUCT((N(OtherInc)+$E8+$G8+CGInc*$F8>ONThr)*((N(OtherInc)+$E8+$G8+CGInc*$F8)-ONThr)*ONDlt)-ONBPA*ONLowRate) | AM8: =$AK8+$AL8+ONSurR1*MAX(0,$AL8-ONSur1)+ONSurR2*MAX(0,$AL8-ONSur2) | AN8: =IF($B8=0,0,$AG8-BaseTaxTotal) | AO8: =$AJ8-$AG8 | AP8: =$AM8-$AJ8 | AQ8: =$AC8-$AM8
